Workbook

Sheet COUNTIF
A1: Serial No. | B1: Name | C1: Annual Income | D1: Marital Status | E1: Education Level | F1: Occupation | G1: Home owner | I1: Marital Status | J1: Total No. | L1: Home owner | M1: Total No.
A2: 1 | B2: Rajiv | C2: 120000 | D2: Y | E2: Gradutaion | F2: Clerk | G2: N | I2: Y | L2: Y
A3: 2 | B3: Suman | C3: 200000 | D3: N | E3: Masters | F3: Manual | G3: Y | I3: N | L3: N
A4: 3 | B4: Rohit | C4: 550000 | D4: Y | E4: Gradutaion | F4: Professional | G4: N
A5: 4 | B5: Aman | C5: 450000 | D5: Y | E5: Masters | F5: Manual | G5: N
A6: 5 | B6: Anjali | C6: 700000 | D6: N | E6: Gradutaion | F6: Professional | G6: Y
A7: 6 | B7: Sanjna | C7: 1200000 | D7: Y | E7: Masters | F7: Professional | G7: Y
A8: 7 | B8: Ritika | C8: 800000 | D8: Y | E8: Gradutaion | F8: Professional | G8: Y
A9: 8 | B9: Rashi | C9: 1500000 | D9: N | E9: Gradutaion | F9: Professional | G9: Y
A10: 9 | B10: Roshan | C10: 1000000 | D10: Y | E10: Gradutaion | F10: Professional | G10: Y
A11: 10 | B11: Yash | C11: 1550000 | D11: N | E11: Masters | F11: Professional | G11: Y
A12: 11 | B12: Randy | C12: 600000 | D12: Y | E12: Masters | F12: HR | G12: N
A13: 12 | B13: Tarun | C13: 500000 | D13: N | E13: Gradutaion | F13: Manual | G13: Y
A14: 13 | B14: Danish | C14: 750000 | D14: Y | E14: Gradutaion | F14: Professional | G14: Y
A15: 14 | B15: Faishal | C15: 800000 | D15: Y | E15: Gradutaion | F15: HR | G15: Y
A16: 15 | B16: Kalam | C16: 1570000 | D16: N | E16: PhD | F16: Professional | G16: N

Sheet SUMIF
A1: Date | B1: Serial No. | C1: Mode of Payment | D1: Amount
A2: 45573 | B2: 1 | C2: Online | D2: 2900 | G2: Mode of Payment | H2: Total Amount | J2: Total No. of Payment Mode
A3: 45573 | B3: 2 | C3: Cash | D3: 6380 | G3: Online | H3: =SUMIF($C$2:$C$21,G3,$D$2:$D$21) -> 56344 | J3: Online | K3: =COUNTIF($C$2:$C$21,J3) -> 9
A4: 45573 | B4: 3 | C4: Cash | D4: 6489 | G4: Cash | H4: =SUMIF($C$2:$C$21,G4,$D$2:$D$21) -> 75999 | J4: Cash | K4: =COUNTIF($C$2:$C$21,J4) -> 11 | Q4: 9212300
A5: 30/08/2024 | B5: 4 | C5: Online | D5: 6499 | G5: All Total | H5: =SUM(H3:H4) -> 132343
A6: 30/08/2024 | B6: 5 | C6: Online | D6: 3549 | J6: Date | K6: 45573
A7: 30/08/2024 | B7: 6 | C7: Cash | D7: 4746
A8: 30/08/2024 | B8: 7 | C8: Cash | D8: 5500 | J8: Sum of Amount
A9: 45573 | B9: 8 | C9: Cash | D9: 7777 | G9: Row Labels | H9: Sum of Total Amount | K9: Cash | L9: Online | M9: Grand Total
A10: 45573 | B10: 9 | C10: Online | D10: 7499 | G10: Online | H10: 56344 | J10: 1 | L10: 2900 | M10: 2900
A11: 30/08/2024 | B11: 10 | C11: Online | D11: 7468 | G11: Grand Total | H11: 56344 | J11: 2 | K11: 6380 | M11: 6380
A12: 30/08/2024 | B12: 11 | C12: Cash | D12: 7476 | J12: 3 | K12: 6489 | M12: 6489
A13: 30/08/2024 | B13: 12 | C13: Online | D13: 8488 | J13: 8 | K13: 7777 | M13: 7777
A14: 30/08/2024 | B14: 13 | C14: Online | D14: 4889 | J14: 9 | L14: 7499 | M14: 7499
A15: 30/08/2024 | B15: 14 | C15: Cash | D15: 7489 | J15: Grand Total | K15: 20646 | L15: 10399 | M15: 31045
A16: 30/08/2024 | B16: 15 | C16: Cash | D16: 7489
A17: 30/08/2024 | B17: 16 | C17: Cash | D17: 7489
A18: 30/08/2024 | B18: 17 | C18: Online | D18: 7484
A19: 30/08/2024 | B19: 18 | C19: Cash | D19: 8675
A20: 30/08/2024 | B20: 19 | C20: Cash | D20: 6489
A21: 30/08/2024 | B21: 20 | C21: Online | D21: 7568

Sheet COUNTIFS
A1: Serial No. | B1: Name | C1: Annual Income | D1: Marital Status | E1: Education Level | F1: Occupation | G1: Home owner | I1: Occupation | J1: Married | K1: Single
A2: 1 | B2: Rajiv | C2: 120000 | D2: Married | E2: Gradutaion | F2: Clerk | G2: N | I2: Professional | J2: =COUNTIFS($F$2:$F$16,$I2,$D$2:$D$16,J$1) -> 5 | K2: =COUNTIFS($F$2:$F$16,$I2,$D$2:$D$16,K$1) -> 4
A3: 2 | B3: Suman | C3: 200000 | D3: Single | E3: Masters | F3: Skilled Manual | G3: Y | I3: Skilled Manual | J3: =COUNTIFS($F$2:$F$16,$I3,$D$2:$D$16,J$1) -> 1 | K3: =COUNTIFS($F$2:$F$16,$I3,$D$2:$D$16,K$1) -> 2
A4: 3 | B4: Rohit | C4: 550000 | D4: Married | E4: Gradutaion | F4: Professional | G4: N | I4: HR | J4: =COUNTIFS($F$2:$F$16,$I4,$D$2:$D$16,J$1) -> 2 | K4: =COUNTIFS($F$2:$F$16,$I4,$D$2:$D$16,K$1) -> 0
A5: 4 | B5: Aman | C5: 450000 | D5: Married | E5: Masters | F5: Skilled Manual | G5: N | I5: Clerk | J5: =COUNTIFS($F$2:$F$16,$I5,$D$2:$D$16,J$1) -> 1 | K5: =COUNTIFS($F$2:$F$16,$I5,$D$2:$D$16,K$1) -> 0
A6: 5 | B6: Anjali | C6: 700000 | D6: Single | E6: Gradutaion | F6: Professional | G6: Y
A7: 6 | B7: Sanjna | C7: 1200000 | D7: Married | E7: Masters | F7: Professional | G7: Y
A8: 7 | B8: Ritika | C8: 800000 | D8: Married | E8: Gradutaion | F8: Professional | G8: Y
A9: 8 | B9: Rashi | C9: 1500000 | D9: Single | E9: Gradutaion | F9: Professional | G9: Y
A10: 9 | B10: Roshan | C10: 1000000 | D10: Married | E10: Gradutaion | F10: Professional | G10: Y
A11: 10 | B11: Yash | C11: 1550000 | D11: Single | E11: Masters | F11: Professional | G11: Y
A12: 11 | B12: Randy | C12: 600000 | D12: Married | E12: Masters | F12: HR | G12: N
A13: 12 | B13: Tarun | C13: 500000 | D13: Single | E13: Gradutaion | F13: Skilled Manual | G13: Y
A14: 13 | B14: Danish | C14: 750000 | D14: Married | E14: Gradutaion | F14: Professional | G14: Y
A15: 14 | B15: Faishal | C15: 800000 | D15: Married | E15: Gradutaion | F15: HR | G15: Y
A16: 15 | B16: Kalam | C16: 1570000 | D16: Single | E16: PhD | F16: Professional | G16: N

Sheet SUMIFS
A1: Serial No. | B1: Name | C1: Annual Income | D1: Marital Status | E1: Education Level | F1: Occupation | G1: Paid | H1: Home owner | J1: Occuapation | K1: Single | L1: Married
A2: 1 | B2: Rajiv | C2: 120000 | D2: Married | E2: Gradutaion | F2: Clerk | G2: =C2/12 -> 10000 | H2: No | J2: Professional
A3: 2 | B3: Suman | C3: 200000 | D3: Single | E3: Masters | F3: Skilled Manual | G3: =C3/12 -> 16666.667 | H3: Yes | J3: Skilled Manual
A4: 3 | B4: Rohit | C4: 550000 | D4: Married | E4: Gradutaion | F4: Professional | G4: =C4/12 -> 45833.333 | H4: No | J4: HR
A5: 4 | B5: Aman | C5: 450000 | D5: Married | E5: Masters | F5: Skilled Manual | G5: =C5/12 -> 37500 | H5: Yes | J5: Clerk
A6: 5 | B6: Anjali | C6: 700000 | D6: Single | E6: Gradutaion | F6: Professional | G6: =C6/12 -> 58333.333 | H6: Yes
A7: 6 | B7: Sanjna | C7: 1200000 | D7: Married | E7: Masters | F7: Professional | G7: =C7/12 -> 100000 | H7: Yes
A8: 7 | B8: Ritika | C8: 800000 | D8: Married | E8: Gradutaion | F8: Professional | G8: =C8/12 -> 66666.667 | H8: Yes
A9: 8 | B9: Rashi | C9: 1500000 | D9: Single | E9: Gradutaion | F9: Professional | G9: =C9/12 -> 125000 | H9: Yes
A10: 9 | B10: Roshan | C10: 1000000 | D10: Married | E10: Gradutaion | F10: Professional | G10: =C10/12 -> 83333.333 | H10: Yes
A11: 10 | B11: Yash | C11: 1550000 | D11: Single | E11: Masters | F11: Professional | G11: =C11/12 -> 129166.67 | H11: Yes
A12: 11 | B12: Randy | C12: 600000 | D12: Single | E12: Masters | F12: HR | G12: =C12/12 -> 50000 | H12: No
A13: 12 | B13: Tarun | C13: 500000 | D13: Single | E13: Gradutaion | F13: Skilled Manual | G13: =C13/12 -> 41666.667 | H13: Yes
A14: 13 | B14: Danish | C14: 750000 | D14: Married | E14: Gradutaion | F14: Professional | G14: =C14/12 -> 62500 | H14: Yes
A15: 14 | B15: Faishal | C15: 800000 | D15: Married | E15: Gradutaion | F15: HR | G15: =C15/12 -> 66666.667 | H15: Yes
A16: 15 | B16: Kalam | C16: 1570000 | D16: Single | E16: PhD | F16: Professional | G16: =C16/12 -> 130833.33 | H16: No

Sheet AVERAGEIF & AVERAGEIFS
A1: Order No | B1: City | C1: Customer Name | D1: Order Date | E1: Status | F1: Order Type | G1: Product | H1: Category | I1: Quantity | J1: Price | K1: Sales Amount | M1: Averageif
A2: 139360 | B2: Mumbai | C2: Anand | D2: 45535 | E2: Ordered | F2: On Shop | G2: Single Monk | H2: Casual | I2: 2 | J2: 15000 | K2: =I2*J2 -> 30000 | N2: Average quantity
A3: 139361 | B3: Mumbai | C3: Amit | D3: 45535 | E3: Ordered | F3: On Shop | G3: Single Monk | H3: Casual | I3: 3 | J3: 15000 | K3: =I3*J3 -> 45000 | M3: Casual
A4: 139362 | B4: Pune | C4: Ritik | D4: 45535 | E4: Ordered | F4: On Shop | G4: Single Monk | H4: Casual | I4: 4 | J4: 15000 | K4: =I4*J4 -> 60000 | M4: Formal
A5: 139363 | B5: Pune | C5: Roshan | D5: 45535 | E5: Ordered | F5: On Shop | G5: Single Monk | H5: Casual | I5: 5 | J5: 15000 | K5: =I5*J5 -> 75000
A6: 139364 | B6: Patna | C6: Amrita | D6: 45535 | E6: Ordered | F6: On Shop | G6: Loafers | H6: Formal | I6: 6 | J6: 20000 | K6: =I6*J6 -> 120000
A7: 139365 | B7: Merut | C7: Sonam | D7: 45535 | E7: Ordered | F7: On Shop | G7: Loafers | H7: Formal | I7: 7 | J7: 20000 | K7: =I7*J7 -> 140000 | M7: Averageifs
A8: 139366 | B8: Merut | C8: Puja | D8: 45535 | E8: Ordered | F8: On Shop | G8: Loafers | H8: Formal | I8: 8 | J8: 20000 | K8: =I8*J8 -> 160000 | N8: On Shop | O8: Online Shop
A9: 139367 | B9: Delhi | C9: Radhika | D9: 45535 | E9: Ordered | F9: Online Shop | G9: Loafers | H9: Formal | I9: 6 | J9: 20000 | K9: =I9*J9 -> 120000 | M9: Casual
A10: 139368 | B10: Delhi | C10: Anant | D10: 45535 | E10: Ordered | F10: On Shop | G10: Loafers | H10: Formal | I10: 5 | J10: 20000 | K10: =I10*J10 -> 100000 | M10: Formal
A11: 139369 | B11: Delhi | C11: Aman | D11: 45535 | E11: Ordered | F11: On Shop | G11: Derby Shoes | H11: Casual | I11: 4 | J11: 35000 | K11: =I11*J11 -> 140000
A12: 139370 | B12: Patna | C12: Ajay | D12: 45535 | E12: Ordered | F12: Online Shop | G12: Derby Shoes | H12: Casual | I12: 3 | J12: 35000 | K12: =I12*J12 -> 105000
A13: 139371 | B13: Pune | C13: Babita | D13: 45535 | E13: Ordered | F13: Online Shop | G13: Derby Shoes | H13: Casual | I13: 2 | J13: 35000 | K13: =I13*J13 -> 70000 | M13: Sumifs
A14: 139372 | B14: Mumbai | C14: Booby | D14: 45536 | E14: Ordered | F14: Online Shop | G14: Derby Shoes | H14: Casual | I14: 3 | J14: 35000 | K14: =I14*J14 -> 105000 | N14: On shop | O14: Online shop
A15: 139373 | B15: Mumbai | C15: Barkha | D15: 45536 | E15: Ordered | F15: Online Shop | G15: Derby Shoes | H15: Casual | I15: 4 | J15: 35000 | K15: =I15*J15 -> 140000 | M15: Casual
A16: 139374 | B16: Delhi | C16: Chameli | D16: 45536 | E16: Ordered | F16: Online Shop | G16: Derby Shoes | H16: Casual | I16: 5 | J16: 35000 | K16: =I16*J16 -> 175000 | M16: Formal
A17: 139375 | B17: Merut | C17: Chandan | D17: 45536 | E17: Ordered | F17: Online Shop | G17: Derby Shoes | H17: Casual | I17: 6 | J17: 35000 | K17: =I17*J17 -> 210000 | N17: Casual | O17: Casual | P17: Formal | Q17: Formal
A18: 139376 | B18: Noida | C18: Deepali | D18: 45536 | E18: Ordered | F18: On Shop | G18: Derby Shoes | H18: Casual | I18: 4 | J18: 35000 | K18: =I18*J18 -> 140000 | M18: Countifs | N18: On Shop | O18: Online Shop | P18: On Shop | Q18: Online Shop
A19: 139377 | B19: Noida | C19: Deepak | D19: 45536 | E19: Ordered | F19: On Shop | G19: Derby Shoes | H19: Casual | I19: 8 | J19: 35000 | K19: =I19*J19 -> 280000 | M19: Mumbai
A20: 139378 | B20: Noida | C20: Deepu | D20: 45536 | E20: Ordered | F20: On Shop | G20: Sneakers | H20: Casual | I20: 9 | J20: 27000 | K20: =I20*J20 -> 243000 | M20: Pune
A21: 139379 | B21: Pune | C21: Deepti | D21: 45537 | E21: Ordered | F21: On Shop | G21: Sneakers | H21: Casual | I21: 6 | J21: 27000 | K21: =I21*J21 -> 162000 | M21: Patna
A22: 139380 | B22: Pune | C22: Faruk | D22: 45537 | E22: Ordered | F22: On Shop | G22: Sneakers | H22: Formal | I22: 8 | J22: 37000 | K22: =I22*J22 -> 296000 | M22: Merut
A23: 139381 | B23: Mumbai | C23: Faishal | D23: 45537 | E23: Ordered | F23: On Shop | G23: Sneakers | H23: Formal | I23: 9 | J23: 37000 | K23: =I23*J23 -> 333000 | M23: Delhi
A24: 139382 | B24: Patna | C24: Fhamita | D24: 45537 | E24: Ordered | F24: On Shop | G24: Oxford Shoes | H24: Formal | I24: 7 | J24: 67000 | K24: =I24*J24 -> 469000 | M24: Noida
A25: 139383 | B25: Patna | C25: Sanket | D25: 45537 | E25: Ordered | F25: On Shop | G25: Oxford Shoes | H25: Formal | I25: 6 | J25: 67000 | K25: =I25*J25 -> 402000

Sheet Date functions
A1: Function | B1: Date | C1: Formula | E1: NetworkDays & NetworkDays.intl
A2: Today | C2: =TODAY() -> 45676
A3: Now | C3: =NOW() -> 45676.496 | E3: Start Date | F3: 45658 | H3: 52 weeks | I3: 365
A4: Day | B4: 45659 | C4: =DAY(B4) -> 2 | E4: End Date | F4: 46022 | H4: 104 Sat & Sun | I4: 104
A5: Month | B5: 45659 | C5: =MONTH(B5) -> 1 | I5: =I3-I4 -> 261
A6: Year | B6: 45659 | C6: =YEAR(B6) -> 2025 | E6: NetworkDays | F6: =NETWORKDAYS(F3,F4) -> 261 | H6: Holidays
A7: Date | C7: =DATE(C6,C5,C4) -> 45659 | E7: NetworkDays | F7: =NETWORKDAYS(F3,F4,H7:H8) -> 259 | H7: =DATE(2025,8,15) -> 45884 | I7: Independence
E8: NetworkDays.intl | F8: =NETWORKDAYS.INTL(F3,F4,11,H7:H8) -> 311 | H8: =DATE(2025,10,2) -> 45932 | I8: Gandhi Jayanti
A10: Add/Subtract Days | E10: DateDif
A11: Date | B11: 45931
A12: Date + 5 days | B12: =B11+C12 -> 45936 | C12: 5 | E12: Date of Birth | F12: Today's Date
A13: Date -5 days | B13: =B11-5 -> 45926 | C13: 5 | E13: =DATE(2000,1,1) -> 36526 | F13: =TODAY() -> 45676
A16: Add/Subtract Months | E16: Total Years | F16: =DATEDIF(E13,F13,"Y") -> 25
A17: Edate | E17: Total Months | F17: =DATEDIF(E13,F13,"M") -> 300
A18: Date | B18: 45931 | E18: Total Days | F18: =DATEDIF(E13,F13,"D") -> 9150
A19: Date + 10 months | B19: =EDATE(B18,C19) -> 46235 | C19: 10
A20: Date - 10 months | B20: =EDATE(B18,-C20) -> 45627 | C20: 10 | E20: Years | F20: =DATEDIF(E13,F13,"Y") -> 25
E21: Months | F21: =DATEDIF(E13,F13,"YM") -> 0
E22: Days | F22: =DATEDIF(E13,F13,"MD") -> 18
A23: Add/Subtract Years
A24: Edate
A25: Date | B25: 45931
A26: Date + 10 Years | B26: =EDATE(B25,C26*12) -> 49583 | C26: 10
A27: Date - 10 Years | B27: =EDATE(B25,-C27*12) -> 42278 | C27: 10

Sheet MATCH & INDEX
A1: JOB VACCENCY REQUIREMENT
A3: DATA ENTRY | B3: GRAPHIC DESIGNING | C3: CYBER SECURITY | D3: ACCOUNTANT | E3: CA | F3: MANAGER | G3: CLERK | H3: DATA ANALYST | I3: BUSINESS ANALYST | J3: MARKETING | K3: SECURITY
A4: EXCEL | B4: CANVA | C4: PENITRATION | D4: TALLY | E4: TALLY | F4: MANAGEMENT | G4: EXCEL | H4: DATA ANALYST COURSE | I4: BUSINESS ANALYST | J4: 12TH OR GRADUATITON | K4: 8TH PASS
A5: MS OFFICE | B5: AQUA | C5: NETWORKING | D5: MS OFFICE | E5: EXCEL | F5: MS OFFICE | G5: MS OFFICE | H5: GRADUATION | I5: 2 YEARS EXPERRINCE IN FIELD | J5: 2 YEARS EXPERRINCE IN FIELD
A6: 12TH PASS | B6: BLENDER | C6: LINUX | D6: EXCEL | E6: CA QUALIFIED | F6: B.COM | G6: 12TH OR GRADUATITON
C7: ETHICAL HACKING | D7: GRADUATION | E7: B.COM | F7: EXPERIENCE Min(2 Years)
C8: PROGRAMMING LANGUAGE
C9: SOCIAL ENGINEERING
C10: GOOD TYPING SPEED
C11: GRADUATION

Sheet SALARY SHEET
A3: Employee ID | B3: Name of Employee | C3: Designation | D3: Employee Status | E3: Fixed Basic | F3: Present | G3: Over Time | H3: Current Month Salary | I3: HRA | J3: TA | K3: DA | L3: Gross Salary | M3: PF | N3: PT | O3: NET Salary
A4: A1101 | B4: Rajiv | C4: Clerk | D4: Unskilled | E4: 6750 | F4: ='ATTENDENCE TRACK'!AN4 -> 29 | G4: ='ATTENDENCE TRACK'!AO4 -> 0 | H4: =E4/30*F4+E4/30/8*G4 -> 6525 | I4: =IF(D4="Unskilled",E4*5%,IF(D4="Skilled",E4*10%,IF(D4="Semiskilled",E4*7%,IF(D4="Proffesional",E4*15%,"")))) -> 337.5 | J4: 800 | K4: =E4/2/12 -> 281.25 | L4: =SUM(H4:K4) -> 7943.75 | M4: =IF(E4>=15000,1800,E4*12%) -> 810 | N4: =IF(L4>10000,200,IF(L4>7500,100,0)) -> 100 | O4: =L4-(M4+N4) -> 7033.75
A5: A1102 | B5: Suman | C5: Supervisor | D5: Skilled | E5: 22500 | F5: ='ATTENDENCE TRACK'!AN5 -> 30 | G5: ='ATTENDENCE TRACK'!AO5 -> 0 | H5: =E5/30*F5+E5/30/8*G5 -> 22500 | I5: =IF(D5="Unskilled",E5*5%,IF(D5="Skilled",E5*10%,IF(D5="Semiskilled",E5*7%,IF(D5="Proffesional",E5*15%,"")))) -> 2250 | J5: 800 | K5: =E5/2/12 -> 937.5 | L5: =SUM(H5:K5) -> 26487.5 | M5: =IF(E5>=15000,1800,E5*12%) -> 1800 | N5: =IF(L5>10000,200,IF(L5>7500,100,0)) -> 200 | O5: =L5-(M5+N5) -> 24487.5
A6: A1103 | B6: Rohit | C6: Clerk | D6: Unskilled | E6: 9000 | F6: ='ATTENDENCE TRACK'!AN6 -> 30 | G6: 1 | H6: =E6/30*F6+E6/30/8*G6 -> 9037.5 | I6: =IF(D6="Unskilled",E6*5%,IF(D6="Skilled",E6*10%,IF(D6="Semiskilled",E6*7%,IF(D6="Proffesional",E6*15%,"")))) -> 450 | J6: 800 | K6: =E6/2/12 -> 375 | L6: =SUM(H6:K6) -> 10662.5 | M6: =IF(E6>=15000,1800,E6*12%) -> 1080 | N6: =IF(L6>10000,200,IF(L6>7500,100,0)) -> 200 | O6: =L6-(M6+N6) -> 9382.5
A7: A1104 | B7: Aman | C7: Clerk | D7: Skilled | E7: 20250 | F7: ='ATTENDENCE TRACK'!AN7 -> 29 | G7: ='ATTENDENCE TRACK'!AO7 -> 1 | H7: =E7/30*F7+E7/30/8*G7 -> 19659.375 | I7: =IF(D7="Unskilled",E7*5%,IF(D7="Skilled",E7*10%,IF(D7="Semiskilled",E7*7%,IF(D7="Proffesional",E7*15%,"")))) -> 2025 | J7: 800 | K7: =E7/2/12 -> 843.75 | L7: =SUM(H7:K7) -> 23328.125 | M7: =IF(E7>=15000,1800,E7*12%) -> 1800 | N7: =IF(L7>10000,200,IF(L7>7500,100,0)) -> 200 | O7: =L7-(M7+N7) -> 21328.125
A8: A1105 | B8: Anjali | C8: Receptionist | D8: Skilled | E8: 18000 | F8: ='ATTENDENCE TRACK'!AN8 -> 29 | G8: ='ATTENDENCE TRACK'!AO8 -> 0 | H8: =E8/30*F8+E8/30/8*G8 -> 17400 | I8: =IF(D8="Unskilled",E8*5%,IF(D8="Skilled",E8*10%,IF(D8="Semiskilled",E8*7%,IF(D8="Proffesional",E8*15%,"")))) -> 1800 | J8: 800 | K8: =E8/2/12 -> 750 | L8: =SUM(H8:K8) -> 20750 | M8: =IF(E8>=15000,1800,E8*12%) -> 1800 | N8: =IF(L8>10000,200,IF(L8>7500,100,0)) -> 200 | O8: =L8-(M8+N8) -> 18750
A9: A1106 | B9: Sanjna | C9: Clerk | D9: Skilled | E9: 17550 | F9: ='ATTENDENCE TRACK'!AN9 -> 29 | G9: ='ATTENDENCE TRACK'!AO9 -> 6 | H9: =E9/30*F9+E9/30/8*G9 -> 17403.75 | I9: =IF(D9="Unskilled",E9*5%,IF(D9="Skilled",E9*10%,IF(D9="Semiskilled",E9*7%,IF(D9="Proffesional",E9*15%,"")))) -> 1755 | J9: 800 | K9: =E9/2/12 -> 731.25 | L9: =SUM(H9:K9) -> 20690 | M9: =IF(E9>=15000,1800,E9*12%) -> 1800 | N9: =IF(L9>10000,200,IF(L9>7500,100,0)) -> 200 | O9: =L9-(M9+N9) -> 18690
A10: A1107 | B10: Ritika | C10: Clerk | D10: Skilled | E10: 13500 | F10: ='ATTENDENCE TRACK'!AN10 -> 29 | G10: ='ATTENDENCE TRACK'!AO10 -> 7 | H10: =E10/30*F10+E10/30/8*G10 -> 13443.75 | I10: =IF(D10="Unskilled",E10*5%,IF(D10="Skilled",E10*10%,IF(D10="Semiskilled",E10*7%,IF(D10="Proffesional",E10*15%,"")))) -> 1350 | J10: 800 | K10: =E10/2/12 -> 562.5 | L10: =SUM(H10:K10) -> 16156.25 | M10: =IF(E10>=15000,1800,E10*12%) -> 1620 | N10: =IF(L10>10000,200,IF(L10>7500,100,0)) -> 200 | O10: =L10-(M10+N10) -> 14336.25
A11: A1108 | B11: Rashi | C11: Clerk | D11: Semiskilled | E11: 14400 | F11: ='ATTENDENCE TRACK'!AN11 -> 29 | G11: ='ATTENDENCE TRACK'!AO11 -> 4 | H11: =E11/30*F11+E11/30/8*G11 -> 14160 | I11: =IF(D11="Unskilled",E11*5%,IF(D11="Skilled",E11*10%,IF(D11="Semiskilled",E11*7%,IF(D11="Proffesional",E11*15%,"")))) -> 1008 | J11: 800 | K11: =E11/2/12 -> 600 | L11: =SUM(H11:K11) -> 16568 | M11: =IF(E11>=15000,1800,E11*12%) -> 1728 | N11: =IF(L11>10000,200,IF(L11>7500,100,0)) -> 200 | O11: =L11-(M11+N11) -> 14640
A12: A1109 | B12: Roshan | C12: Manager | D12: Proffesional | E12: 67500 | F12: ='ATTENDENCE TRACK'!AN12 -> 29 | G12: ='ATTENDENCE TRACK'!AO12 -> 2 | H12: =E12/30*F12+E12/30/8*G12 -> 65812.5 | I12: =IF(D12="Unskilled",E12*5%,IF(D12="Skilled",E12*10%,IF(D12="Semiskilled",E12*7%,IF(D12="Proffesional",E12*15%,"")))) -> 10125 | J12: 800 | K12: =E12/2/12 -> 2812.5 | L12: =SUM(H12:K12) -> 79550 | M12: =IF(E12>=15000,1800,E12*12%) -> 1800 | N12: =IF(L12>10000,200,IF(L12>7500,100,0)) -> 200 | O12: =L12-(M12+N12) -> 77550
A13: A1110 | B13: Yash | C13: HR | D13: Proffesional | E13: 40500 | F13: ='ATTENDENCE TRACK'!AN13 -> 30 | G13: ='ATTENDENCE TRACK'!AO13 -> 0 | H13: =E13/30*F13+E13/30/8*G13 -> 40500 | I13: =IF(D13="Unskilled",E13*5%,IF(D13="Skilled",E13*10%,IF(D13="Semiskilled",E13*7%,IF(D13="Proffesional",E13*15%,"")))) -> 6075 | J13: 800 | K13: =E13/2/12 -> 1687.5 | L13: =SUM(H13:K13) -> 49062.5 | M13: =IF(E13>=15000,1800,E13*12%) -> 1800 | N13: =IF(L13>10000,200,IF(L13>7500,100,0)) -> 200 | O13: =L13-(M13+N13) -> 47062.5
A14: A1111 | B14: Randy | C14: Supervisor | D14: Skilled | E14: 29250 | F14: ='ATTENDENCE TRACK'!AN14 -> 29 | G14: ='ATTENDENCE TRACK'!AO14 -> 1 | H14: =E14/30*F14+E14/30/8*G14 -> 28396.875 | I14: =IF(D14="Unskilled",E14*5%,IF(D14="Skilled",E14*10%,IF(D14="Semiskilled",E14*7%,IF(D14="Proffesional",E14*15%,"")))) -> 2925 | J14: 800 | K14: =E14/2/12 -> 1218.75 | L14: =SUM(H14:K14) -> 33340.625 | M14: =IF(E14>=15000,1800,E14*12%) -> 1800 | N14: =IF(L14>10000,200,IF(L14>7500,100,0)) -> 200 | O14: =L14-(M14+N14) -> 31340.625
A15: A1112 | B15: Tarun | C15: Clerk | D15: Skilled | E15: 25650 | F15: ='ATTENDENCE TRACK'!AN15 -> 30 | G15: ='ATTENDENCE TRACK'!AO15 -> 3 | H15: =E15/30*F15+E15/30/8*G15 -> 25970.625 | I15: =IF(D15="Unskilled",E15*5%,IF(D15="Skilled",E15*10%,IF(D15="Semiskilled",E15*7%,IF(D15="Proffesional",E15*15%,"")))) -> 2565 | J15: 800 | K15: =E15/2/12 -> 1068.75 | L15: =SUM(H15:K15) -> 30404.375 | M15: =IF(E15>=15000,1800,E15*12%) -> 1800 | N15: =IF(L15>10000,200,IF(L15>7500,100,0)) -> 200 | O15: =L15-(M15+N15) -> 28404.375
A16: A1113 | B16: Danish | C16: Developer | D16: Proffesional | E16: 40050 | F16: ='ATTENDENCE TRACK'!AN16 -> 30 | G16: ='ATTENDENCE TRACK'!AO16 -> 5 | H16: =E16/30*F16+E16/30/8*G16 -> 40884.375 | I16: =IF(D16="Unskilled",E16*5%,IF(D16="Skilled",E16*10%,IF(D16="Semiskilled",E16*7%,IF(D16="Proffesional",E16*15%,"")))) -> 6007.5 | J16: 800 | K16: =E16/2/12 -> 1668.75 | L16: =SUM(H16:K16) -> 49360.625 | M16: =IF(E16>=15000,1800,E16*12%) -> 1800 | N16: =IF(L16>10000,200,IF(L16>7500,100,0)) -> 200 | O16: =L16-(M16+N16) -> 47360.625
A17: A1114 | B17: Faishal | C17: Clerk | D17: Skilled | E17: 25650 | F17: ='ATTENDENCE TRACK'!AN17 -> 29 | G17: ='ATTENDENCE TRACK'!AO17 -> 4 | H17: =E17/30*F17+E17/30/8*G17 -> 25222.5 | I17: =IF(D17="Unskilled",E17*5%,IF(D17="Skilled",E17*10%,IF(D17="Semiskilled",E17*7%,IF(D17="Proffesional",E17*15%,"")))) -> 2565 | J17: 800 | K17: =E17/2/12 -> 1068.75 | L17: =SUM(H17:K17) -> 29656.25 | M17: =IF(E17>=15000,1800,E17*12%) -> 1800 | N17: =IF(L17>10000,200,IF(L17>7500,100,0)) -> 200 | O17: =L17-(M17+N17) -> 27656.25
A18: A1115 | B18: Kalam | C18: CA | D18: Proffesional | E18: 76500 | F18: ='ATTENDENCE TRACK'!AN18 -> 29 | G18: ='ATTENDENCE TRACK'!AO18 -> 3 | H18: =E18/30*F18+E18/30/8*G18 -> 74906.25 | I18: =IF(D18="Unskilled",E18*5%,IF(D18="Skilled",E18*10%,IF(D18="Semiskilled",E18*7%,IF(D18="Proffesional",E18*15%,"")))) -> 11475 | J18: 800 | K18: =E18/2/12 -> 3187.5 | L18: =SUM(H18:K18) -> 90368.75 | M18: =IF(E18>=15000,1800,E18*12%) -> 1800 | N18: =IF(L18>10000,200,IF(L18>7500,100,0)) -> 200 | O18: =L18-(M18+N18) -> 88368.75
N20: STATE TO STATE VARY
A21: PF | N21: PT
A22: 15000*12% | B22: CELLING | C22: ACTUAL | D22: SALARY IF LESS THAN 15000 | E22: ctc | F22: 1700000 | H22: UNSKILLED | I22: 0.05 | K22: TA | L22: 9600 | N22: >10000 | O22: 200
A23: EE | B23: 1800 | C23: 0.12 | D23: SALARY<15000 | E23: gross | F23: =F22*90% -> 1530000 | H23: SKILLED | I23: 0.1 | L23: =L22/12 -> 800 | N23: >7500 | O23: 100
A24: ER | B24: 1800 | C24: 0.12 | D24: SALARY*12% | E24: basic | F24: =F23*60% -> 918000 | G24: =F24/12 -> 76500 | H24: PROFFESIONAL | I24: 0.15

Sheet ATTENDENCE TRACK
E2: =TEXT(E$3,"ddd") -> Sun | F2: =TEXT(F$3,"ddd") -> Mon | G2: =TEXT(G$3,"ddd") -> Tue | H2: =TEXT(H$3,"ddd") -> Wed | I2: =TEXT(I$3,"ddd") -> Thu | J2: =TEXT(J$3,"ddd") -> Fri | K2: =TEXT(K$3,"ddd") -> Sat | L2: =TEXT(L$3,"ddd") -> Sun | ... AH2: =TEXT(AH$3,"ddd") -> Mon
A3: Employee ID | B3: Name of Employee | C3: Designation | D3: Employee Status | E3: 45536 | F3: 45537 | G3: 45538 | H3: 45539 | I3: 45540 | J3: 45541 | K3: 45542 | L3: 45543 | M3: 45544 | N3: 45545 | O3: 45546 | P3: 45547 | Q3: 45548 | R3: 45549 | S3: 45550 | T3: 45551 | U3: 45552 | V3: 45553 | W3: 45554 | X3: 45555 | Y3: 45556 | Z3: 45557 | AA3: 45558 | AB3: 45559 | AC3: 45560 | AD3: 45561 | AE3: 45562 | AF3: 45563 | AG3: 45564 | AH3: 45565 | AI3: Present | AJ3: Absent | AK3: SL | AL3: PL | AM3: W.Off | AN3: Present Days | AO3: Over Time
A4: A1101 | B4: Rajiv | C4: Clerk | D4: Unskilled | F4: P | G4: PL | H4: P | I4: P | J4: SL | K4: P | M4: P | N4: P | O4: P | P4: P | Q4: P | R4: P | T4: P | U4: P | V4: P | W4: P | X4: AB | Y4: P | AA4: P | AB4: P | AC4: P | AD4: PL | AE4: P | AF4: P | AH4: P | AI4: =COUNTIF($E4:$AH4,"P") -> 21 | AJ4: =COUNTIF($E4:$AH4,"AB") -> 1 | AK4: =COUNTIF($E4:$AH4,AK$3) -> 1 | AL4: =COUNTIF($E4:$AH4,AL$3) -> 2 | AM4: =COUNTBLANK($E4:$AH4) -> 5 | AN4: =SUM(AI4+AK4+AL4+AM4) -> 29 | AO4: 0
A5: A1102 | B5: Suman | C5: Supervisor | D5: Skilled | F5: P | G5: P | H5: P | I5: P | J5: P | K5: P | M5: P | N5: P | O5: P | P5: P | Q5: P | R5: SL | T5: P | U5: P | V5: P | W5: P | X5: P | Y5: P | AA5: P | AB5: P | AC5: PL | AD5: P | AE5: P | AF5: P | AH5: P | AI5: =COUNTIF($E5:$AH5,"P") -> 23 | AJ5: =COUNTIF($E5:$AH5,"AB") -> 0 | AK5: =COUNTIF($E5:$AH5,AK$3) -> 1 | AL5: =COUNTIF($E5:$AH5,AL$3) -> 1 | AM5: =COUNTBLANK($E5:$AH5) -> 5 | AN5: =SUM(AI5+AK5+AL5+AM5) -> 30 | AO5: 0
A6: A1103 | B6: Rohit | C6: Clerk | D6: Unskilled | F6: P | G6: P | H6: P | I6: P | J6: P | K6: P | M6: P | N6: P | O6: P | P6: P | Q6: P | R6: P | T6: P | U6: P | V6: P | W6: P | X6: P | Y6: P | AA6: P | AB6: P | AC6: P | AD6: P | AE6: P | AF6: P | AH6: P | AI6: =COUNTIF($E6:$AH6,"P") -> 25 | AJ6: =COUNTIF($E6:$AH6,"AB") -> 0 | AK6: =COUNTIF($E6:$AH6,AK$3) -> 0 | AL6: =COUNTIF($E6:$AH6,AL$3) -> 0 | AM6: =COUNTBLANK($E6:$AH6) -> 5 | AN6: =SUM(AI6+AK6+AL6+AM6) -> 30 | AO6: 0
A7: A1104 | B7: Aman | C7: Clerk | D7: Skilled | F7: P | G7: P | H7: P | I7: P | J7: P | K7: P | M7: P | N7: P | O7: SL | P7: P | Q7: P | R7: P | T7: P | U7: P | V7: P | W7: P | X7: P | Y7: P | AA7: P | AB7: P | AC7: P | AD7: P | AE7: PL | AF7: P | AH7: AB | AI7: =COUNTIF($E7:$AH7,"P") -> 22 | AJ7: =COUNTIF($E7:$AH7,"AB") -> 1 | AK7: =COUNTIF($E7:$AH7,AK$3) -> 1 | AL7: =COUNTIF($E7:$AH7,AL$3) -> 1 | AM7: =COUNTBLANK($E7:$AH7) -> 5 | AN7: =SUM(AI7+AK7+AL7+AM7) -> 29 | AO7: 1
A8: A1105 | B8: Anjali | C8: Receptionist | D8: Skilled | F8: P | G8: AB | H8: P | I8: P | J8: P | K8: P | M8: P | N8: P | O8: P | P8: P | Q8: P | R8: P | T8: P | U8: P | V8: P | W8: P | X8: P | Y8: P | AA8: PL | AB8: P | AC8: P | AD8: P | AE8: P | AF8: P | AH8: P | AI8: =COUNTIF($E8:$AH8,"P") -> 23 | AJ8: =COUNTIF($E8:$AH8,"AB") -> 1 | AK8: =COUNTIF($E8:$AH8,AK$3) -> 0 | AL8: =COUNTIF($E8:$AH8,AL$3) -> 1 | AM8: =COUNTBLANK($E8:$AH8) -> 5 | AN8: =SUM(AI8+AK8+AL8+AM8) -> 29 | AO8: 0
A9: A1106 | B9: Sanjna | C9: Clerk | D9: Skilled | F9: P | G9: P | H9: P | I9: P | J9: P | K9: P | M9: P | N9: P | O9: P | P9: P | Q9: P | R9: P | T9: P | U9: P | V9: P | W9: P | X9: P | Y9: P | AA9: P | AB9: P | AC9: SL | AD9: P | AE9: P | AF9: AB | AH9: P | AI9: =COUNTIF($E9:$AH9,"P") -> 23 | AJ9: =COUNTIF($E9:$AH9,"AB") -> 1 | AK9: =COUNTIF($E9:$AH9,AK$3) -> 1 | AL9: =COUNTIF($E9:$AH9,AL$3) -> 0 | AM9: =COUNTBLANK($E9:$AH9) -> 5 | AN9: =SUM(AI9+AK9+AL9+AM9) -> 29 | AO9: 6
A10: A1107 | B10: Ritika | C10: Clerk | D10: Skilled | F10: P | G10: P | H10: P | I10: P | J10: P | K10: P | M10: AB | N10: P | O10: P | P10: P | Q10: P | R10: P | T10: P | U10: P | V10: P | W10: P | X10: P | Y10: P | AA10: P | AB10: P | AC10: P | AD10: P | AE10: P | AF10: P | AH10: P | AI10: =COUNTIF($E10:$AH10,"P") -> 24 | AJ10: =COUNTIF($E10:$AH10,"AB") -> 1 | AK10: =COUNTIF($E10:$AH10,AK$3) -> 0 | AL10: =COUNTIF($E10:$AH10,AL$3) -> 0 | AM10: =COUNTBLANK($E10:$AH10) -> 5 | AN10: =SUM(AI10+AK10+AL10+AM10) -> 29 | AO10: 7
A11: A1108 | B11: Rashi | C11: Clerk | D11: Semiskilled | F11: P | G11: P | H11: P | I11: P | J11: P | K11: P | M11: P | N11: P | O11: P | P11: P | Q11: P | R11: P | T11: P | U11: P | V11: P | W11: P | X11: P | Y11: AB | AA11: P | AB11: P | AC11: P | AD11: P | AE11: P | AF11: P | AH11: P | AI11: =COUNTIF($E11:$AH11,"P") -> 24 | AJ11: =COUNTIF($E11:$AH11,"AB") -> 1 | AK11: =COUNTIF($E11:$AH11,AK$3) -> 0 | AL11: =COUNTIF($E11:$AH11,AL$3) -> 0 | AM11: =COUNTBLANK($E11:$AH11) -> 5 | AN11: =SUM(AI11+AK11+AL11+AM11) -> 29 | AO11: 4
A12: A1109 | B12: Roshan | C12: Manager | D12: Proffesional | F12: P | G12: P | H12: P | I12: P | J12: P | K12: P | M12: P | N12: P | O12: P | P12: P | Q12: AB | R12: P | T12: P | U12: P | V12: P | W12: P | X12: P | Y12: P | AA12: P | AB12: P | AC12: P | AD12: P | AE12: P | AF12: P | AH12: P | AI12: =COUNTIF($E12:$AH12,"P") -> 24 | AJ12: =COUNTIF($E12:$AH12,"AB") -> 1 | AK12: =COUNTIF($E12:$AH12,AK$3) -> 0 | AL12: =COUNTIF($E12:$AH12,AL$3) -> 0 | AM12: =COUNTBLANK($E12:$AH12) -> 5 | AN12: =SUM(AI12+AK12+AL12+AM12) -> 29 | AO12: 2
A13: A1110 | B13: Yash | C13: HR | D13: Proffesional | F13: P | G13: P | H13: P | I13: P | J13: P | K13: P | M13: P | N13: P | O13: P | P13: P | Q13: P | R13: P | T13: SL | U13: P | V13: P | W13: P | X13: P | Y13: P | AA13: P | AB13: P | AC13: P | AD13: P | AE13: P | AF13: P | AH13: P | AI13: =COUNTIF($E13:$AH13,"P") -> 24 | AJ13: =COUNTIF($E13:$AH13,"AB") -> 0 | AK13: =COUNTIF($E13:$AH13,AK$3) -> 1 | AL13: =COUNTIF($E13:$AH13,AL$3) -> 0 | AM13: =COUNTBLANK($E13:$AH13) -> 5 | AN13: =SUM(AI13+AK13+AL13+AM13) -> 30 | AO13: 0
A14: A1111 | B14: Randy | C14: Supervisor | D14: Skilled | F14: P | G14: P | H14: P | I14: P | J14: P | K14: SL | M14: P | N14: P | O14: P | P14: P | Q14: P | R14: P | T14: P | U14: P | V14: P | W14: P | X14: P | Y14: P | AA14: P | AB14: P | AC14: AB | AD14: P | AE14: P | AF14: P | AH14: P | AI14: =COUNTIF($E14:$AH14,"P") -> 23 | AJ14: =COUNTIF($E14:$AH14,"AB") -> 1 | AK14: =COUNTIF($E14:$AH14,AK$3) -> 1 | AL14: =COUNTIF($E14:$AH14,AL$3) -> 0 | AM14: =COUNTBLANK($E14:$AH14) -> 5 | AN14: =SUM(AI14+AK14+AL14+AM14) -> 29 | AO14: 1
A15: A1112 | B15: Tarun | C15: Clerk | D15: Skilled | F15: P | G15: P | H15: P | I15: P | J15: P | K15: P | M15: P | N15: P | O15: P | P15: P | Q15: P | R15: SL | T15: P | U15: P | V15: P | W15: PL | X15: P | Y15: P | AA15: P | AB15: P | AC15: P | AD15: P | AE15: P | AF15: P | AH15: P | AI15: =COUNTIF($E15:$AH15,"P") -> 23 | AJ15: =COUNTIF($E15:$AH15,"AB") -> 0 | AK15: =COUNTIF($E15:$AH15,AK$3) -> 1 | AL15: =COUNTIF($E15:$AH15,AL$3) -> 1 | AM15: =COUNTBLANK($E15:$AH15) -> 5 | AN15: =SUM(AI15+AK15+AL15+AM15) -> 30 | AO15: 3
... A18: A1115 | B18: Kalam | C18: CA | D18: Proffesional | F18: P | G18: P | H18: SL | I18: P | J18: P | K18: P | M18: P | N18: P | O18: P | P18: AB | Q18: P | R18: P | T18: P | U18: P | V18: P | W18: P | X18: P | Y18: P | AA18: P | AB18: P | AC18: P | AD18: P | AE18: P | AF18: P | AH18: P | AI18: =COUNTIF($E18:$AH18,"P") -> 23 | AJ18: =COUNTIF($E18:$AH18,"AB") -> 1 | AK18: =COUNTIF($E18:$AH18,AK$3) -> 1 | AL18: =COUNTIF($E18:$AH18,AL$3) -> 0 | AM18: =COUNTBLANK($E18:$AH18) -> 5 | AN18: =SUM(AI18+AK18+AL18+AM18) -> 29 | AO18: 3

Sheet SALARY SLIP
A1: TECH SKILLS PVT LTD
A2: A-2, Basement Premnagar, Uttam Nagar west, Exit Gate No. 4, Opp metro station Pillar No. 685, Delhi - 110059
A5: Employee ID | B5: A1101 | C5: PF A/c No.
A6: Employee Name | B6: =VLOOKUP($B$5,'SALARY SHEET'!$A$3:$O$18,ROW()-4,0) -> Rajiv | C6: Esic A/c No.
A7: Designation | B7: =VLOOKUP($B$5,'SALARY SHEET'!$A$3:$O$18,ROW()-4,0) -> Clerk | C7: Bank A/c No.
A8: Skills | B8: =VLOOKUP($B$5,'SALARY SHEET'!$A$3:$O$18,ROW()-4,0) -> Unskilled | C8: IFSC No.
A9: Present Days | B9: =VLOOKUP($B$5,'SALARY SHEET'!$A$3:$O$18,6,0) -> 29
A10: Over Time | B10: =VLOOKUP($B$5,'SALARY SHEET'!$A$3:$O$18,7,0) -> 0
A12: Earning | C12: Deduction
A13: Basic Salary | B13: =VLOOKUP($B$5,'SALARY SHEET'!$A$3:$O$18,5,0) -> 6750 | C13: PF | D13: =VLOOKUP($B$5,'SALARY SHEET'!$A$3:$O$18,13,0) -> 810
A14: HRA | B14: =VLOOKUP($B$5,'SALARY SHEET'!$A$3:$O$18,9,0) -> 337.5 | C14: PT | D14: =VLOOKUP($B$5,'SALARY SHEET'!$A$3:$O$18,14,0) -> 100
A15: TA | B15: =VLOOKUP($B$5,'SALARY SHEET'!$A$3:$O$18,10,0) -> 800
A16: DA | B16: =VLOOKUP($B$5,'SALARY SHEET'!$A$3:$O$18,11,0) -> 281.25
A17: Gross Salary | B17: =VLOOKUP($B$5,'SALARY SHEET'!$A$3:$O$18,12,0) -> 7943.75 | C17: NET | D17: =VLOOKUP($B$5,'SALARY SHEET'!$A$3:$O$18,15,0) -> 7033.75

Sheet vlookup(1)
A1: VLOOKUP(EXECT & APPROXIMATE) | L1: VLOOKUP(IFERROR)
A3: Employee ID | B3: Name | C3: Designation | D3: Salary | E3: Score | F3: Performance | I3: Employee ID | J3: A1002 | L3: Employee ID | M3: A1014
A4: A1001 | B4: Amit | C4: Staff | D4: 15000 | E4: 42 | F4: =VLOOKUP($E4,$I$10:$J$14,MATCH($F$3,$I$10:$J$10,0),1) -> Not Good | I4: Name | J4: =VLOOKUP($J$3,$A$3:$F$23,MATCH($I4,$A$3:$F$3,0),0) -> Varun | L4: Name | M4: =IFERROR(VLOOKUP($M$3,$A$3:$F$23,MATCH($L4,$A$3:$F$3,0),0),"Invalid") -> Sohan
A5: A1002 | B5: Varun | C5: Graphic Designing | D5: 19000 | E5: 77 | F5: =VLOOKUP($E5,$I$10:$J$14,MATCH($F$3,$I$10:$J$10,0),1) -> Good | I5: Designation | J5: =VLOOKUP($J$3,$A$3:$F$23,MATCH($I5,$A$3:$F$3,0),0) -> Graphic Designing | L5: Designation | M5: =IFERROR(VLOOKUP($M$3,$A$3:$F$23,MATCH($L5,$A$3:$F$3,0),0),"Invalid") -> Staff
A6: A1003 | B6: Harsh | C6: Excel Operator | D6: 25000 | E6: 84 | F6: =VLOOKUP($E6,$I$10:$J$14,MATCH($F$3,$I$10:$J$10,0),1) -> Good | I6: Salary | J6: =VLOOKUP($J$3,$A$3:$F$23,MATCH($I6,$A$3:$F$3,0),0) -> 19000 | L6: Salary | M6: =IFERROR(VLOOKUP($M$3,$A$3:$F$23,MATCH($L6,$A$3:$F$3,0),0),"Invalid") -> 11000
A7: A1004 | B7: Tanishka | C7: Programmer | D7: 45000 | E7: 80 | F7: =VLOOKUP($E7,$I$10:$J$14,MATCH($F$3,$I$10:$J$10,0),1) -> Good | I7: Performance | J7: =VLOOKUP($J$3,$A$3:$F$23,MATCH($I7,$A$3:$F$3,0),0) -> Good | L7: Performance | M7: =IFERROR(VLOOKUP($M$3,$A$3:$F$23,MATCH($L7,$A$3:$F$3,0),0),"Invalid") -> Not Good
A8: A1005 | B8: Tannu | C8: Developer | D8: 65000 | E8: 99 | F8: =VLOOKUP($E8,$I$10:$J$14,MATCH($F$3,$I$10:$J$10,0),1) -> Awesome
A9: A1006 | B9: Amit | C9: Staff | D9: 15000 | E9: 36 | F9: =VLOOKUP($E9,$I$10:$J$14,MATCH($F$3,$I$10:$J$10,0),1) -> Not Good
A10: A1007 | B10: Akansha | C10: Staff | D10: 15000 | E10: 43 | F10: =VLOOKUP($E10,$I$10:$J$14,MATCH($F$3,$I$10:$J$10,0),1) -> Not Good | I10: Score | J10: Performance
A11: A1008 | B11: Samikchha | C11: Staff | D11: 15000 | E11: 68 | F11: =VLOOKUP($E11,$I$10:$J$14,MATCH($F$3,$I$10:$J$10,0),1) -> Average | I11: 30 | J11: Not Good
A12: A1009 | B12: Yash | C12: Excel Operator | D12: 25000 | E12: 79 | F12: =VLOOKUP($E12,$I$10:$J$14,MATCH($F$3,$I$10:$J$10,0),1) -> Good | I12: 50 | J12: Average
A13: A1010 | B13: Vivek | C13: Graphic Designing | D13: 20000 | E13: 69 | F13: =VLOOKUP($E13,$I$10:$J$14,MATCH($F$3,$I$10:$J$10,0),1) -> Average | I13: 70 | J13: Good
A14: A1011 | B14: Rohit | C14: Staff | D14: 16000 | E14: 44 | F14: =VLOOKUP($E14,$I$10:$J$14,MATCH($F$3,$I$10:$J$10,0),1) -> Not Good | I14: 90 | J14: Awesome
A15: A1012 | B15: Maya | C15: Staff | D15: 12000 | E15: 86 | F15: =VLOOKUP($E15,$I$10:$J$14,MATCH($F$3,$I$10:$J$10,0),1) -> Good
A16: A1013 | B16: Ritik | C16: Staff | D16: 13000 | E16: 50 | F16: =VLOOKUP($E16,$I$10:$J$14,MATCH($F$3,$I$10:$J$10,0),1) -> Average
A17: A1014 | B17: Sohan | C17: Staff | D17: 11000 | E17: 32 | F17: =VLOOKUP($E17,$I$10:$J$14,MATCH($F$3,$I$10:$J$10,0),1) -> Not Good
A18: A1015 | B18: Mohan | C18: Staff | D18: 16000 | E18: 42 | F18: =VLOOKUP($E18,$I$10:$J$14,MATCH($F$3,$I$10:$J$10,0),1) -> Not Good | H18: Employee ID | I18: Name | J18: Designation | K18: Salary | L18: Performance
A19: A1016 | B19: Ramu | C19: Staff | D19: 17000 | E19: 58 | F19: =VLOOKUP($E19,$I$10:$J$14,MATCH($F$3,$I$10:$J$10,0),1) -> Average | H19: A1019 | I19: =VLOOKUP($H$19,$A$3:$F$23,MATCH(I$18,$A$3:$F$3,0),0) -> Amit | J19: =VLOOKUP($H$19,$A:$F,MATCH(J$18,$A$3:$F$3,0),0) -> Staff | K19: =VLOOKUP($H$19,$A:$F,MATCH(K$18,$A$3:$F$3,0),0) -> 14000 | L19: =VLOOKUP($H$19,$A:$F,MATCH(L$18,$A$3:$F$3,0),1) -> Awesome
A20: A1017 | B20: Shara | C20: Staff | D20: 16000 | E20: 78 | F20: =VLOOKUP($E20,$I$10:$J$14,MATCH($F$3,$I$10:$J$10,0),1) -> Good
A21: A1018 | B21: Faisal | C21: Staff | D21: 15000 | E21: 88 | F21: =VLOOKUP($E21,$I$10:$J$14,MATCH($F$3,$I$10:$J$10,0),1) -> Good | H21: NESTED VLOOKUP
A22: A1019 | B22: Amit | C22: Staff | D22: 14000 | E22: 92 | F22: =VLOOKUP($E22,$I$10:$J$14,MATCH($F$3,$I$10:$J$10,0),1) -> Awesome
A23: A1020 | B23: Vivek | C23: Staff | D23: 15000 | E23: 82 | F23: =VLOOKUP($E23,$I$10:$J$14,MATCH($F$3,$I$10:$J$10,0),1) -> Good
G24: Enrollment Id | H24: Board Id | J24: Board Id | K24: Name | L24: Stream | M24: State | N24: Marks
G25: 1001 | H25: B1001 | J25: B1001 | K25: Ramu | L25: Science | M25: Delhi | N25: 77
G26: 1002 | H26: B1002 | J26: B1002 | K26: Shara | L26: Arts | M26: Delhi | N26: 80
G27: 1003 | H27: B1003 | J27: B1003 | K27: Faisal | L27: Commerce | M27: Delhi | N27: 90
G28: 1004 | H28: B1004 | J28: B1004 | K28: Amit | L28: Commerce | M28: Delhi | N28: 89
G29: 1005 | H29: B1005 | J29: B1005 | K29: Vivek | L29: Science | M29: Delhi | N29: 79
G31: Enrollment Id | H31: Board Id | I31: Name | J31: Stream | K31: State | L31: Marks
G32: 1003 | H32: =VLOOKUP(VLOOKUP($G$32,$G$24:$H$29,MATCH($H$31,$G$24:$H$24,0),0),$J$24:$N$29,MATCH(H$31,$J$24:$N$24,0),0) -> B1003 | I32: =VLOOKUP(VLOOKUP($G$32,$G$24:$H$29,MATCH($H$31,$G$24:$H$24,0),0),$J$24:$N$29,MATCH(I$31,$J$24:$N$24,0),0) -> Faisal | J32: =VLOOKUP(VLOOKUP($G$32,$G$24:$H$29,MATCH($H$31,$G$24:$H$24,0),0),$J$24:$N$29,MATCH(J$31,$J$24:$N$24,0),0) -> Commerce | K32: =VLOOKUP(VLOOKUP($G$32,$G$24:$H$29,MATCH($H$31,$G$24:$H$24,0),0),$J$24:$N$29,MATCH(K$31,$J$24:$N$24,0),0) -> Delhi | L32: =VLOOKUP(VLOOKUP($G$32,$G$24:$H$29,MATCH($H$31,$G$24:$H$24,0),0),$J$24:$N$29,MATCH(L$31,$J$24:$N$24,0),0) -> 90
G34: FILTER USING VLOOKUP
G37: UNIQUE ID | H37: PRODUCT | I37: ZONE | J37: SALES | M37: PRODUCT
G38: =H38&COUNTIF($H$38:H38,H38) -> Iodex1 | H38: Iodex | I38: South City | J38: 30 | M38: Toothbrush
G39: =H39&COUNTIF($H$38:H39,H39) -> Tigerbalm1 | H39: Tigerbalm | I39: North City | J39: 24
G40: =H40&COUNTIF($H$38:H40,H40) -> Toothbrush1 | H40: Toothbrush | I40: West City | J40: 54 | M40: PRODUCT | N40: ZONE | O40: SALES
G41: =H41&COUNTIF($H$38:H41,H41) -> Iodex2 | H41: Iodex | I41: East City | J41: 38 | M41: =VLOOKUP($M$38&ROW()-40,$G$37:$J$46,MATCH(M$40,$G$37:$J$37,0),0) -> Toothbrush | N41: =VLOOKUP($M$38&ROW()-40,$G$37:$J$46,MATCH(N$40,$G$37:$J$37,0),0) -> West City | O41: =VLOOKUP($M$38&ROW()-40,$G$37:$J$46,MATCH(O$40,$G$37:$J$37,0),0) -> 54
G42: =H42&COUNTIF($H$38:H42,H42) -> Tigerbalm2 | H42: Tigerbalm | I42: North City | J42: 47 | M42: =VLOOKUP($M$38&ROW()-40,$G$37:$J$46,MATCH(M$40,$G$37:$J$37,0),0) -> Toothbrush | N42: =VLOOKUP($M$38&ROW()-40,$G$37:$J$46,MATCH(N$40,$G$37:$J$37,0),0) -> East City | O42: =VLOOKUP($M$38&ROW()-40,$G$37:$J$46,MATCH(O$40,$G$37:$J$37,0),0) -> 40
G43: =H43&COUNTIF($H$38:H43,H43) -> Toothbrush2 | H43: Toothbrush | I43: East City | J43: 40 | M43: =IFERROR(VLOOKUP($M$38&ROW()-40,$G$37:$J$46,MATCH(M$40,$G$37:$J$37,0),0),"") | N43: =IFERROR(VLOOKUP($M$38&ROW()-40,$G$37:$J$46,MATCH(N$40,$G$37:$J$37,0),0),"") | O43: =IFERROR(VLOOKUP($M$38&ROW()-40,$G$37:$J$46,MATCH(O$40,$G$37:$J$37,0),0),"")
G44: =H44&COUNTIF($H$38:H44,H44) -> Zandubalm1 | H44: Zandubalm | I44: West City | J44: 42 | M44: =IFERROR(VLOOKUP($M$38&ROW()-40,$G$37:$J$46,MATCH(M$40,$G$37:$J$37,0),0),"") | N44: =IFERROR(VLOOKUP($M$38&ROW()-40,$G$37:$J$46,MATCH(N$40,$G$37:$J$37,0),0),"") | O44: =IFERROR(VLOOKUP($M$38&ROW()-40,$G$37:$J$46,MATCH(O$40,$G$37:$J$37,0),0),"")
G45: =H45&COUNTIF($H$38:H45,H45) -> Zandubalm2 | H45: Zandubalm | I45: North City | J45: 36
...

Sheet vlookup(2)
A1: Vlookup on Multiple Table/Sheets
A3: Date | B3: 45565 | E3: Date | F3: 45566 | I3: Date | J3: 45567
A4: Bill No. | B4: Product | C4: Quantity | E4: Bill No. | F4: Product | G4: Quantity | I4: Bill No. | J4: Product | K4: Quantity
A5: 1001 | B5: Sun Cream | C5: 2 | E5: 1011 | F5: Complane | G5: 6 | I5: 1021 | J5: Nano | K5: 5
A6: 1002 | B6: Face Cream | C6: 4 | E6: 1012 | F6: Vitamins Tab. | G6: 9 | I6: 1022 | J6: Protein | K6: 3
A7: 1003 | B7: Iodex | C7: 2 | E7: 1013 | F7: Iodex | G7: 3 | I7: 1023 | J7: Lipids | K7: 5
A8: 1004 | B8: Horlicks | C8: 7 | E8: 1014 | F8: Shampoo | G8: 5 | I8: 1024 | J8: P90 | K8: 7
A9: 1005 | B9: Shampoo | C9: 1 | E9: 1015 | F9: Orthodex | G9: 2 | I9: 1025 | J9: Paracetamol | K9: 8
A10: 1006 | B10: Nimoset | C10: 3 | E10: 1016 | F10: Nimoset | G10: 9 | I10: 1026 | J10: Orthodex | K10: 4
A11: 1007 | B11: Chest&Cold | C11: 8 | E11: 1017 | F11: Paracetamol | G11: 4 | I11: 1027 | J11: Nimocet | K11: 3
A12: 1008 | B12: Vitamins Tab. | C12: 4 | E12: 1018 | F12: Cornflex | G12: 7 | I12: 1028 | J12: Minerals | K12: 3
A13: 1009 | B13: Minerals | C13: 3 | E13: 1019 | F13: Minerals | G13: 5 | I13: 1029 | J13: Horlicks | K13: 5
A14: 1010 | B14: Orthodex | C14: 8 | E14: 1020 | F14: Horlicks | G14: 3 | I14: 1030 | J14: Toothpaste | K14: 7
E17: Bill No. | F17: 1030
E18: Product | F18: =VLOOKUP($F$17,IF($F$17<=1010,$A$4:$C$14,IF($F$17<=1020,$E$4:$G$14,$I$4:$K$14)),MATCH($E18,$A$4:$C$4,0),0) -> Toothpaste
E19: Quantity | F19: =VLOOKUP($F$17,IF($F$17<=1010,$A$4:$C$14,IF($F$17<=1020,$E$4:$G$14,$I$4:$K$14)),MATCH($E19,$A$4:$C$4,0),0) -> 7

Sheet Bank Account Detals
A1: Account No. | B1: Name | C1: IFSC Code | D1: Customer Id | E1: A/C open Date | F1: No. Code | G1: Phone No. | H1: Account Balance | I1: Nationality
A2: 684854613020983 | B2: Narina Kumari | C2: ABI3023 | D2: 15633379 | E2: 43815 | F2: 91 | G2: 9583518243 | H2: 64891 | I2: =IF(F2=91,"India",IF(F2=1,"United Staes",IF(F2=7,"Russia",IF(F2=34,"Spain",IF(F2=45,"Denmark",IF(F2=33,"France",IF(F2=61,"Australia",IF(F2=49,"German",IF(F2=81,"Japan",IF(F2=55,"Brazil",IF(F2=44,"United Kindom",IF(F2=27,"South Africa",IF(F2=380,"Ukrain",IF(F2=48,"Poland",IF(F2=82,"South Korea",IF(F2=966,"Saudi Arabia",IF(F2=41,"Swizerland",IF(F2=975,"Bhutan",IF(F2=974,"Qatar",IF(F2=977,"Nepal",IF(F2=972,"Isreal",IF(F2=93,"Afghanistan",IF(F2=351,"Portugal",IF(F2=54,"Argentina",IF(F2=374,"Armrnia",IF(F2=64,"New Zealand",IF(F2=62,"Indonesia",IF(F2=39,"Italy",IF(F2=46,"Sweden",IF(F2=58,"Venezuela",IF(F2=57,"Colombia",IF(F2=63,"Philippines",IF(F2=850,"North Korea",IF(F2=976,"Mongolia","Not exist in this Nation")))))))))))))))))))))))))))))))))) -> India | K2: Account No.
A3: 312192816249982 | B3: Sushmita | C3: ABI3024 | D3: 13697273 | E3: 44641 | F3: 91 | G3: 9650882171 | H3: 67492 | I3: =IF(F3=91,"India",IF(F3=1,"United Staes",IF(F3=7,"Russia",IF(F3=34,"Spain",IF(F3=45,"Denmark",IF(F3=33,"France",IF(F3=61,"Australia",IF(F3=49,"German",IF(F3=81,"Japan",IF(F3=55,"Brazil",IF(F3=44,"United Kindom",IF(F3=27,"South Africa",IF(F3=380,"Ukrain",IF(F3=48,"Poland",IF(F3=82,"South Korea",IF(F3=966,"Saudi Arabia",IF(F3=41,"Swizerland",IF(F3=975,"Bhutan",IF(F3=974,"Qatar",IF(F3=977,"Nepal",IF(F3=972,"Isreal",IF(F3=93,"Afghanistan",IF(F3=351,"Portugal",IF(F3=54,"Argentina",IF(F3=374,"Armrnia",IF(F3=64,"New Zealand",IF(F3=62,"Indonesia",IF(F3=39,"Italy",IF(F3=46,"Sweden",IF(F3=58,"Venezuela",IF(F3=57,"Colombia",IF(F3=63,"Philippines",IF(F3=850,"North Korea",IF(F3=976,"Mongolia","Not exist in this Nation")))))))))))))))))))))))))))))))))) -> India | K3: 9470925566
A4: 592469086934245 | B4: Anamika Saini | C4: ABI3025 | D4: 14390885 | E4: 42598 | F4: 91 | G4: 9274325193 | H4: 69833 | I4: =IF(F4=91,"India",IF(F4=1,"United Staes",IF(F4=7,"Russia",IF(F4=34,"Spain",IF(F4=45,"Denmark",IF(F4=33,"France",IF(F4=61,"Australia",IF(F4=49,"German",IF(F4=81,"Japan",IF(F4=55,"Brazil",IF(F4=44,"United Kindom",IF(F4=27,"South Africa",IF(F4=380,"Ukrain",IF(F4=48,"Poland",IF(F4=82,"South Korea",IF(F4=966,"Saudi Arabia",IF(F4=41,"Swizerland",IF(F4=975,"Bhutan",IF(F4=974,"Qatar",IF(F4=977,"Nepal",IF(F4=972,"Isreal",IF(F4=93,"Afghanistan",IF(F4=351,"Portugal",IF(F4=54,"Argentina",IF(F4=374,"Armrnia",IF(F4=64,"New Zealand",IF(F4=62,"Indonesia",IF(F4=39,"Italy",IF(F4=46,"Sweden",IF(F4=58,"Venezuela",IF(F4=57,"Colombia",IF(F4=63,"Philippines",IF(F4=850,"North Korea",IF(F4=976,"Mongolia","Not exist in this Nation")))))))))))))))))))))))))))))))))) -> India | J4: Account No. | K4: {=IFERROR(VLOOKUP($K$3,Table24[#All],MATCH($J4,Table24[#Headers],0),0),VLOOKUP($K$3,CHOOSE({1,2,3,4,5,6,7,8,9},Table24[[#All],[Phone No.]],Table24[[#All],[Account No.]],Table24[[#All],[Name]],Table24[[#All],[IFSC Code]],Table24[[#All],[Customer Id]],Table24[[#All],[A/C open Date]],Table24[[#All],[No. Code]],Table24[[#All],[Account Balance]],Table24[[#All],[Nationality]]),ROW()-2,0))} -> 600384878210911
A5: 665558081702523 | B5: Trivedi Kumar | C5: ABI3026 | D5: 14108301 | E5: 43924 | F5: 91 | G5: 9499837088 | H5: 82996 | I5: =IF(F5=91,"India",IF(F5=1,"United Staes",IF(F5=7,"Russia",IF(F5=34,"Spain",IF(F5=45,"Denmark",IF(F5=33,"France",IF(F5=61,"Australia",IF(F5=49,"German",IF(F5=81,"Japan",IF(F5=55,"Brazil",IF(F5=44,"United Kindom",IF(F5=27,"South Africa",IF(F5=380,"Ukrain",IF(F5=48,"Poland",IF(F5=82,"South Korea",IF(F5=966,"Saudi Arabia",IF(F5=41,"Swizerland",IF(F5=975,"Bhutan",IF(F5=974,"Qatar",IF(F5=977,"Nepal",IF(F5=972,"Isreal",IF(F5=93,"Afghanistan",IF(F5=351,"Portugal",IF(F5=54,"Argentina",IF(F5=374,"Armrnia",IF(F5=64,"New Zealand",IF(F5=62,"Indonesia",IF(F5=39,"Italy",IF(F5=46,"Sweden",IF(F5=58,"Venezuela",IF(F5=57,"Colombia",IF(F5=63,"Philippines",IF(F5=850,"North Korea",IF(F5=976,"Mongolia","Not exist in this Nation")))))))))))))))))))))))))))))))))) -> India | J5: Name | K5: {=IFERROR(VLOOKUP($K$3,Table24[#All],MATCH($J5,Table24[#Headers],0),0),VLOOKUP($K$3,CHOOSE({1,2,3,4,5,6,7,8,9},Table24[[#All],[Phone No.]],Table24[[#All],[Account No.]],Table24[[#All],[Name]],Table24[[#All],[IFSC Code]],Table24[[#All],[Customer Id]],Table24[[#All],[A/C open Date]],Table24[[#All],[No. Code]],Table24[[#All],[Account Balance]],Table24[[#All],[Nationality]]),ROW()-2,0))} -> Taj Pal
A6: 529606325730995 | B6: Rajat Singh | C6: ABI3027 | D6: 14031139 | E6: 43704 | F6: 91 | G6: 9900471462 | H6: 89674 | I6: =IF(F6=91,"India",IF(F6=1,"United Staes",IF(F6=7,"Russia",IF(F6=34,"Spain",IF(F6=45,"Denmark",IF(F6=33,"France",IF(F6=61,"Australia",IF(F6=49,"German",IF(F6=81,"Japan",IF(F6=55,"Brazil",IF(F6=44,"United Kindom",IF(F6=27,"South Africa",IF(F6=380,"Ukrain",IF(F6=48,"Poland",IF(F6=82,"South Korea",IF(F6=966,"Saudi Arabia",IF(F6=41,"Swizerland",IF(F6=975,"Bhutan",IF(F6=974,"Qatar",IF(F6=977,"Nepal",IF(F6=972,"Isreal",IF(F6=93,"Afghanistan",IF(F6=351,"Portugal",IF(F6=54,"Argentina",IF(F6=374,"Armrnia",IF(F6=64,"New Zealand",IF(F6=62,"Indonesia",IF(F6=39,"Italy",IF(F6=46,"Sweden",IF(F6=58,"Venezuela",IF(F6=57,"Colombia",IF(F6=63,"Philippines",IF(F6=850,"North Korea",IF(F6=976,"Mongolia","Not exist in this Nation")))))))))))))))))))))))))))))))))) -> India | J6: IFSC Code | K6: {=IFERROR(VLOOKUP($K$3,Table24[#All],MATCH($J6,Table24[#Headers],0),0),VLOOKUP($K$3,CHOOSE({1,2,3,4,5,6,7,8,9},Table24[[#All],[Phone No.]],Table24[[#All],[Account No.]],Table24[[#All],[Name]],Table24[[#All],[IFSC Code]],Table24[[#All],[Customer Id]],Table24[[#All],[A/C open Date]],Table24[[#All],[No. Code]],Table24[[#All],[Account Balance]],Table24[[#All],[Nationality]]),ROW()-2,0))} -> ABI3030
A7: 671597281912738 | B7: Amrit Pal | C7: ABI3028 | D7: 13767861 | E7: 43179 | F7: 91 | G7: 9957757502 | H7: 51312 | I7: =IF(F7=91,"India",IF(F7=1,"United Staes",IF(F7=7,"Russia",IF(F7=34,"Spain",IF(F7=45,"Denmark",IF(F7=33,"France",IF(F7=61,"Australia",IF(F7=49,"German",IF(F7=81,"Japan",IF(F7=55,"Brazil",IF(F7=44,"United Kindom",IF(F7=27,"South Africa",IF(F7=380,"Ukrain",IF(F7=48,"Poland",IF(F7=82,"South Korea",IF(F7=966,"Saudi Arabia",IF(F7=41,"Swizerland",IF(F7=975,"Bhutan",IF(F7=974,"Qatar",IF(F7=977,"Nepal",IF(F7=972,"Isreal",IF(F7=93,"Afghanistan",IF(F7=351,"Portugal",IF(F7=54,"Argentina",IF(F7=374,"Armrnia",IF(F7=64,"New Zealand",IF(F7=62,"Indonesia",IF(F7=39,"Italy",IF(F7=46,"Sweden",IF(F7=58,"Venezuela",IF(F7=57,"Colombia",IF(F7=63,"Philippines",IF(F7=850,"North Korea",IF(F7=976,"Mongolia","Not exist in this Nation")))))))))))))))))))))))))))))))))) -> India | J7: Customer Id | K7: {=IFERROR(VLOOKUP($K$3,Table24[#All],MATCH($J7,Table24[#Headers],0),0),VLOOKUP($K$3,CHOOSE({1,2,3,4,5,6,7,8,9},Table24[[#All],[Phone No.]],Table24[[#All],[Account No.]],Table24[[#All],[Name]],Table24[[#All],[IFSC Code]],Table24[[#All],[Customer Id]],Table24[[#All],[A/C open Date]],Table24[[#All],[No. Code]],Table24[[#All],[Account Balance]],Table24[[#All],[Nationality]]),ROW()-2,0))} -> 13654354
A8: 771342004086235 | B8: Ashwin Khumeni | C8: ABI3029 | D8: 15065222 | E8: 43582 | F8: 91 | G8: 9801587468 | H8: 92235 | I8: =IF(F8=91,"India",IF(F8=1,"United Staes",IF(F8=7,"Russia",IF(F8=34,"Spain",IF(F8=45,"Denmark",IF(F8=33,"France",IF(F8=61,"Australia",IF(F8=49,"German",IF(F8=81,"Japan",IF(F8=55,"Brazil",IF(F8=44,"United Kindom",IF(F8=27,"South Africa",IF(F8=380,"Ukrain",IF(F8=48,"Poland",IF(F8=82,"South Korea",IF(F8=966,"Saudi Arabia",IF(F8=41,"Swizerland",IF(F8=975,"Bhutan",IF(F8=974,"Qatar",IF(F8=977,"Nepal",IF(F8=972,"Isreal",IF(F8=93,"Afghanistan",IF(F8=351,"Portugal",IF(F8=54,"Argentina",IF(F8=374,"Armrnia",IF(F8=64,"New Zealand",IF(F8=62,"Indonesia",IF(F8=39,"Italy",IF(F8=46,"Sweden",IF(F8=58,"Venezuela",IF(F8=57,"Colombia",IF(F8=63,"Philippines",IF(F8=850,"North Korea",IF(F8=976,"Mongolia","Not exist in this Nation")))))))))))))))))))))))))))))))))) -> India | J8: A/C open Date | K8: {=IFERROR(VLOOKUP($K$3,Table24[#All],MATCH($J8,Table24[#Headers],0),0),VLOOKUP($K$3,CHOOSE({1,2,3,4,5,6,7,8,9},Table24[[#All],[Phone No.]],Table24[[#All],[Account No.]],Table24[[#All],[Name]],Table24[[#All],[IFSC Code]],Table24[[#All],[Customer Id]],Table24[[#All],[A/C open Date]],Table24[[#All],[No. Code]],Table24[[#All],[Account Balance]],Table24[[#All],[Nationality]]),ROW()-2,0))} -> 45341
A9: 600384878210911 | B9: Taj Pal | C9: ABI3030 | D9: 13654354 | E9: 45341 | F9: 91 | G9: 9470925566 | H9: 32024 | I9: =IF(F9=91,"India",IF(F9=1,"United Staes",IF(F9=7,"Russia",IF(F9=34,"Spain",IF(F9=45,"Denmark",IF(F9=33,"France",IF(F9=61,"Australia",IF(F9=49,"German",IF(F9=81,"Japan",IF(F9=55,"Brazil",IF(F9=44,"United Kindom",IF(F9=27,"South Africa",IF(F9=380,"Ukrain",IF(F9=48,"Poland",IF(F9=82,"South Korea",IF(F9=966,"Saudi Arabia",IF(F9=41,"Swizerland",IF(F9=975,"Bhutan",IF(F9=974,"Qatar",IF(F9=977,"Nepal",IF(F9=972,"Isreal",IF(F9=93,"Afghanistan",IF(F9=351,"Portugal",IF(F9=54,"Argentina",IF(F9=374,"Armrnia",IF(F9=64,"New Zealand",IF(F9=62,"Indonesia",IF(F9=39,"Italy",IF(F9=46,"Sweden",IF(F9=58,"Venezuela",IF(F9=57,"Colombia",IF(F9=63,"Philippines",IF(F9=850,"North Korea",IF(F9=976,"Mongolia","Not exist in this Nation")))))))))))))))))))))))))))))))))) -> India | J9: No. Code | K9: {=IFERROR(VLOOKUP($K$3,Table24[#All],MATCH($J9,Table24[#Headers],0),0),VLOOKUP($K$3,CHOOSE({1,2,3,4,5,6,7,8,9},Table24[[#All],[Phone No.]],Table24[[#All],[Account No.]],Table24[[#All],[Name]],Table24[[#All],[IFSC Code]],Table24[[#All],[Customer Id]],Table24[[#All],[A/C open Date]],Table24[[#All],[No. Code]],Table24[[#All],[Account Balance]],Table24[[#All],[Nationality]]),ROW()-2,0))} -> 91
A10: 160601338343158 | B10: Neepu Trivedi | C10: ABI3031 | D10: 14697304 | E10: 44679 | F10: 91 | G10: 9832109063 | H10: 92614 | I10: =IF(F10=91,"India",IF(F10=1,"United Staes",IF(F10=7,"Russia",IF(F10=34,"Spain",IF(F10=45,"Denmark",IF(F10=33,"France",IF(F10=61,"Australia",IF(F10=49,"German",IF(F10=81,"Japan",IF(F10=55,"Brazil",IF(F10=44,"United Kindom",IF(F10=27,"South Africa",IF(F10=380,"Ukrain",IF(F10=48,"Poland",IF(F10=82,"South Korea",IF(F10=966,"Saudi Arabia",IF(F10=41,"Swizerland",IF(F10=975,"Bhutan",IF(F10=974,"Qatar",IF(F10=977,"Nepal",IF(F10=972,"Isreal",IF(F10=93,"Afghanistan",IF(F10=351,"Portugal",IF(F10=54,"Argentina",IF(F10=374,"Armrnia",IF(F10=64,"New Zealand",IF(F10=62,"Indonesia",IF(F10=39,"Italy",IF(F10=46,"Sweden",IF(F10=58,"Venezuela",IF(F10=57,"Colombia",IF(F10=63,"Philippines",IF(F10=850,"North Korea",IF(F10=976,"Mongolia","Not exist in this Nation")))))))))))))))))))))))))))))))))) -> India | J10: Phone No. | K10: {=IFERROR(VLOOKUP($K$3,Table24[#All],MATCH($J10,Table24[#Headers],0),0),VLOOKUP($K$3,CHOOSE({1,2,3,4,5,6,7,8,9},Table24[[#All],[Phone No.]],Table24[[#All],[Account No.]],Table24[[#All],[Name]],Table24[[#All],[IFSC Code]],Table24[[#All],[Customer Id]],Table24[[#All],[A/C open Date]],Table24[[#All],[No. Code]],Table24[[#All],[Account Balance]],Table24[[#All],[Nationality]]),1,0))} -> 9470925566
A11: 594157466642130 | B11: Yashika Kumari | C11: ABI3032 | D11: 14755921 | E11: 42596 | F11: 91 | G11: 9353366248 | H11: 15406 | I11: =IF(F11=91,"India",IF(F11=1,"United Staes",IF(F11=7,"Russia",IF(F11=34,"Spain",IF(F11=45,"Denmark",IF(F11=33,"France",IF(F11=61,"Australia",IF(F11=49,"German",IF(F11=81,"Japan",IF(F11=55,"Brazil",IF(F11=44,"United Kindom",IF(F11=27,"South Africa",IF(F11=380,"Ukrain",IF(F11=48,"Poland",IF(F11=82,"South Korea",IF(F11=966,"Saudi Arabia",IF(F11=41,"Swizerland",IF(F11=975,"Bhutan",IF(F11=974,"Qatar",IF(F11=977,"Nepal",IF(F11=972,"Isreal",IF(F11=93,"Afghanistan",IF(F11=351,"Portugal",IF(F11=54,"Argentina",IF(F11=374,"Armrnia",IF(F11=64,"New Zealand",IF(F11=62,"Indonesia",IF(F11=39,"Italy",IF(F11=46,"Sweden",IF(F11=58,"Venezuela",IF(F11=57,"Colombia",IF(F11=63,"Philippines",IF(F11=850,"North Korea",IF(F11=976,"Mongolia","Not exist in this Nation")))))))))))))))))))))))))))))))))) -> India | J11: Account Balance | K11: {=IFERROR(VLOOKUP($K$3,Table24[#All],MATCH($J11,Table24[#Headers],0),0),VLOOKUP($K$3,CHOOSE({1,2,3,4,5,6,7,8,9},Table24[[#All],[Phone No.]],Table24[[#All],[Account No.]],Table24[[#All],[Name]],Table24[[#All],[IFSC Code]],Table24[[#All],[Customer Id]],Table24[[#All],[A/C open Date]],Table24[[#All],[No. Code]],Table24[[#All],[Account Balance]],Table24[[#All],[Nationality]]),ROW()-3,0))} -> 32024
A12: 287105317477148 | B12: Anaya Sharma | C12: ABI3033 | D12: 14183310 | E12: 45228 | F12: 91 | G12: 9681731416 | H12: 70722 | I12: =IF(F12=91,"India",IF(F12=1,"United Staes",IF(F12=7,"Russia",IF(F12=34,"Spain",IF(F12=45,"Denmark",IF(F12=33,"France",IF(F12=61,"Australia",IF(F12=49,"German",IF(F12=81,"Japan",IF(F12=55,"Brazil",IF(F12=44,"United Kindom",IF(F12=27,"South Africa",IF(F12=380,"Ukrain",IF(F12=48,"Poland",IF(F12=82,"South Korea",IF(F12=966,"Saudi Arabia",IF(F12=41,"Swizerland",IF(F12=975,"Bhutan",IF(F12=974,"Qatar",IF(F12=977,"Nepal",IF(F12=972,"Isreal",IF(F12=93,"Afghanistan",IF(F12=351,"Portugal",IF(F12=54,"Argentina",IF(F12=374,"Armrnia",IF(F12=64,"New Zealand",IF(F12=62,"Indonesia",IF(F12=39,"Italy",IF(F12=46,"Sweden",IF(F12=58,"Venezuela",IF(F12=57,"Colombia",IF(F12=63,"Philippines",IF(F12=850,"North Korea",IF(F12=976,"Mongolia","Not exist in this Nation")))))))))))))))))))))))))))))))))) -> India | J12: Nationality | K12: {=IFERROR(VLOOKUP($K$3,Table24[#All],MATCH($J12,Table24[#Headers],0),0),VLOOKUP($K$3,CHOOSE({1,2,3,4,5,6,7,8,9},Table24[[#All],[Phone No.]],Table24[[#All],[Account No.]],Table24[[#All],[Name]],Table24[[#All],[IFSC Code]],Table24[[#All],[Customer Id]],Table24[[#All],[A/C open Date]],Table24[[#All],[No. Code]],Table24[[#All],[Account Balance]],Table24[[#All],[Nationality]]),ROW()-3,0))} -> India
A13: 787748411717474 | B13: Arpika Saini | C13: ABI3034 | D13: 15165567 | E13: 42919 | F13: 91 | G13: 9179954964 | H13: 90471 | I13: =IF(F13=91,"India",IF(F13=1,"United Staes",IF(F13=7,"Russia",IF(F13=34,"Spain",IF(F13=45,"Denmark",IF(F13=33,"France",IF(F13=61,"Australia",IF(F13=49,"German",IF(F13=81,"Japan",IF(F13=55,"Brazil",IF(F13=44,"United Kindom",IF(F13=27,"South Africa",IF(F13=380,"Ukrain",IF(F13=48,"Poland",IF(F13=82,"South Korea",IF(F13=966,"Saudi Arabia",IF(F13=41,"Swizerland",IF(F13=975,"Bhutan",IF(F13=974,"Qatar",IF(F13=977,"Nepal",IF(F13=972,"Isreal",IF(F13=93,"Afghanistan",IF(F13=351,"Portugal",IF(F13=54,"Argentina",IF(F13=374,"Armrnia",IF(F13=64,"New Zealand",IF(F13=62,"Indonesia",IF(F13=39,"Italy",IF(F13=46,"Sweden",IF(F13=58,"Venezuela",IF(F13=57,"Colombia",IF(F13=63,"Philippines",IF(F13=850,"North Korea",IF(F13=976,"Mongolia","Not exist in this Nation")))))))))))))))))))))))))))))))))) -> India
A14: 763458971638737 | B14: Santosh Kumar | C14: ABI3035 | D14: 15115776 | E14: 45279 | F14: 91 | G14: 9938253112 | H14: 8649 | I14: =IF(F14=91,"India",IF(F14=1,"United Staes",IF(F14=7,"Russia",IF(F14=34,"Spain",IF(F14=45,"Denmark",IF(F14=33,"France",IF(F14=61,"Australia",IF(F14=49,"German",IF(F14=81,"Japan",IF(F14=55,"Brazil",IF(F14=44,"United Kindom",IF(F14=27,"South Africa",IF(F14=380,"Ukrain",IF(F14=48,"Poland",IF(F14=82,"South Korea",IF(F14=966,"Saudi Arabia",IF(F14=41,"Swizerland",IF(F14=975,"Bhutan",IF(F14=974,"Qatar",IF(F14=977,"Nepal",IF(F14=972,"Isreal",IF(F14=93,"Afghanistan",IF(F14=351,"Portugal",IF(F14=54,"Argentina",IF(F14=374,"Armrnia",IF(F14=64,"New Zealand",IF(F14=62,"Indonesia",IF(F14=39,"Italy",IF(F14=46,"Sweden",IF(F14=58,"Venezuela",IF(F14=57,"Colombia",IF(F14=63,"Philippines",IF(F14=850,"North Korea",IF(F14=976,"Mongolia","Not exist in this Nation")))))))))))))))))))))))))))))))))) -> India
A15: 318191840280056 | B15: Jaspreet Singh | C15: ABI3036 | D15: 13754374 | E15: 43945 | F15: 91 | G15: 9447794116 | H15: 74861 | I15: =IF(F15=91,"India",IF(F15=1,"United Staes",IF(F15=7,"Russia",IF(F15=34,"Spain",IF(F15=45,"Denmark",IF(F15=33,"France",IF(F15=61,"Australia",IF(F15=49,"German",IF(F15=81,"Japan",IF(F15=55,"Brazil",IF(F15=44,"United Kindom",IF(F15=27,"South Africa",IF(F15=380,"Ukrain",IF(F15=48,"Poland",IF(F15=82,"South Korea",IF(F15=966,"Saudi Arabia",IF(F15=41,"Swizerland",IF(F15=975,"Bhutan",IF(F15=974,"Qatar",IF(F15=977,"Nepal",IF(F15=972,"Isreal",IF(F15=93,"Afghanistan",IF(F15=351,"Portugal",IF(F15=54,"Argentina",IF(F15=374,"Armrnia",IF(F15=64,"New Zealand",IF(F15=62,"Indonesia",IF(F15=39,"Italy",IF(F15=46,"Sweden",IF(F15=58,"Venezuela",IF(F15=57,"Colombia",IF(F15=63,"Philippines",IF(F15=850,"North Korea",IF(F15=976,"Mongolia","Not exist in this Nation")))))))))))))))))))))))))))))))))) -> India
A16: 580977965243922 | B16: Kartik Singh | C16: ABI3037 | D16: 15502447 | E16: 45231 | F16: 91 | G16: 9859874524 | H16: 98851 | I16: =IF(F16=91,"India",IF(F16=1,"United Staes",IF(F16=7,"Russia",IF(F16=34,"Spain",IF(F16=45,"Denmark",IF(F16=33,"France",IF(F16=61,"Australia",IF(F16=49,"German",IF(F16=81,"Japan",IF(F16=55,"Brazil",IF(F16=44,"United Kindom",IF(F16=27,"South Africa",IF(F16=380,"Ukrain",IF(F16=48,"Poland",IF(F16=82,"South Korea",IF(F16=966,"Saudi Arabia",IF(F16=41,"Swizerland",IF(F16=975,"Bhutan",IF(F16=974,"Qatar",IF(F16=977,"Nepal",IF(F16=972,"Isreal",IF(F16=93,"Afghanistan",IF(F16=351,"Portugal",IF(F16=54,"Argentina",IF(F16=374,"Armrnia",IF(F16=64,"New Zealand",IF(F16=62,"Indonesia",IF(F16=39,"Italy",IF(F16=46,"Sweden",IF(F16=58,"Venezuela",IF(F16=57,"Colombia",IF(F16=63,"Philippines",IF(F16=850,"North Korea",IF(F16=976,"Mongolia","Not exist in this Nation")))))))))))))))))))))))))))))))))) -> India
A17: 425147226825317 | B17: Gourav Arya | C17: ABI3038 | D17: 15223037 | E17: 44019 | F17: 91 | G17: 9431075203 | H17: 83129 | I17: =IF(F17=91,"India",IF(F17=1,"United Staes",IF(F17=7,"Russia",IF(F17=34,"Spain",IF(F17=45,"Denmark",IF(F17=33,"France",IF(F17=61,"Australia",IF(F17=49,"German",IF(F17=81,"Japan",IF(F17=55,"Brazil",IF(F17=44,"United Kindom",IF(F17=27,"South Africa",IF(F17=380,"Ukrain",IF(F17=48,"Poland",IF(F17=82,"South Korea",IF(F17=966,"Saudi Arabia",IF(F17=41,"Swizerland",IF(F17=975,"Bhutan",IF(F17=974,"Qatar",IF(F17=977,"Nepal",IF(F17=972,"Isreal",IF(F17=93,"Afghanistan",IF(F17=351,"Portugal",IF(F17=54,"Argentina",IF(F17=374,"Armrnia",IF(F17=64,"New Zealand",IF(F17=62,"Indonesia",IF(F17=39,"Italy",IF(F17=46,"Sweden",IF(F17=58,"Venezuela",IF(F17=57,"Colombia",IF(F17=63,"Philippines",IF(F17=850,"North Korea",IF(F17=976,"Mongolia","Not exist in this Nation")))))))))))))))))))))))))))))))))) -> India
A18: 547738492633233 | B18: Gourav Singh | C18: ABI3039 | D18: 15263488 | E18: 45402 | F18: 91 | G18: 9669000718 | H18: 80785 | I18: =IF(F18=91,"India",IF(F18=1,"United Staes",IF(F18=7,"Russia",IF(F18=34,"Spain",IF(F18=45,"Denmark",IF(F18=33,"France",IF(F18=61,"Australia",IF(F18=49,"German",IF(F18=81,"Japan",IF(F18=55,"Brazil",IF(F18=44,"United Kindom",IF(F18=27,"South Africa",IF(F18=380,"Ukrain",IF(F18=48,"Poland",IF(F18=82,"South Korea",IF(F18=966,"Saudi Arabia",IF(F18=41,"Swizerland",IF(F18=975,"Bhutan",IF(F18=974,"Qatar",IF(F18=977,"Nepal",IF(F18=972,"Isreal",IF(F18=93,"Afghanistan",IF(F18=351,"Portugal",IF(F18=54,"Argentina",IF(F18=374,"Armrnia",IF(F18=64,"New Zealand",IF(F18=62,"Indonesia",IF(F18=39,"Italy",IF(F18=46,"Sweden",IF(F18=58,"Venezuela",IF(F18=57,"Colombia",IF(F18=63,"Philippines",IF(F18=850,"North Korea",IF(F18=976,"Mongolia","Not exist in this Nation")))))))))))))))))))))))))))))))))) -> India
