Workbook
Name Slicer_Product_Name: #N/A

Sheet Working Sheet

Sheet Monthly Sales
B1: Product Name | C1: Jan(1) | D1: Feb(2) | E1: Mar(3) | F1: Apr(4) | G1: May(5) | H1: Jun(6) | I1: Jul(7) | J1: Aug(8) | K1: Sep(9) | L1: Oct(10) | M1: Nov(11) | N1: Dec(12) | O1: Total (Year) | P1: Type | Q1: Month Wise | R1: Month wise(No.) | S1: Average sales
B2: Iodex | C2: ='Daily Sales(JAN)'!AH3 -> 179 | D2: =Februray!AH3 -> 177 | E2: =March!AH3 -> 166 | F2: =Aprail!AH3 -> 137 | G2: =May!AH3 -> 144 | H2: =June!AH3 -> 165 | I2: =July!AH3 -> 169 | J2: =August!AH3 -> 160 | K2: =September!AH3 -> 147 | L2: =October!AH3 -> 83 | M2: =November!AH3 -> 83 | N2: =December!AH3 -> 83 | O2: =SUM(C2:N2) -> 1693 | P2: Branded | Q2: =SUM(C2:OFFSET(C2,0,$R$2-1)) -> 659 | R2: 4 | S2: =AVERAGE(C2:N2) -> 141.08333
B3: Nimocet | C3: ='Daily Sales(JAN)'!AH4 -> 179 | D3: =Februray!AH4 -> 203 | E3: =March!AH4 -> 163 | F3: =Aprail!AH4 -> 157 | G3: =May!AH4 -> 171 | H3: =June!AH4 -> 162 | I3: =July!AH4 -> 181 | J3: =August!AH4 -> 157 | K3: =September!AH4 -> 165 | L3: =October!AH4 | M3: =November!AH4 | N3: =December!AH4 | O3: =SUM(C3:N3) -> 1538 | P3: Branded | Q3: =SUM(C3:OFFSET(C3,0,$R$2-1)) -> 702 | S3: =AVERAGE(C3:N3) -> 170.88889
B4: Paracetamol | C4: ='Daily Sales(JAN)'!AH5 -> 177 | D4: =Februray!AH5 -> 161 | E4: =March!AH5 -> 182 | F4: =Aprail!AH5 -> 172 | G4: =May!AH5 -> 193 | H4: =June!AH5 -> 165 | I4: =July!AH5 -> 216 | J4: =August!AH5 -> 178 | K4: =September!AH5 -> 176 | L4: =October!AH5 | M4: =November!AH5 | N4: =December!AH5 | O4: =SUM(C4:N4) -> 1620 | P4: Generic | Q4: =SUM(C4:OFFSET(C4,0,$R$2-1)) -> 692 | S4: =AVERAGE(C4:N4) -> 180
B5: Monocef | C5: ='Daily Sales(JAN)'!AH6 -> 170 | D5: =Februray!AH6 -> 142 | E5: =March!AH6 -> 182 | F5: =Aprail!AH6 -> 167 | G5: =May!AH6 -> 163 | H5: =June!AH6 -> 152 | I5: =July!AH6 -> 177 | J5: =August!AH6 -> 186 | K5: =September!AH6 -> 159 | L5: =October!AH6 | M5: =November!AH6 | N5: =December!AH6 | O5: =SUM(C5:N5) -> 1498 | P5: Generic | Q5: =SUM(C5:OFFSET(C5,0,$R$2-1)) -> 661 | S5: =AVERAGE(C5:N5) -> 166.44444
B6: Cyclopalm | C6: ='Daily Sales(JAN)'!AH7 -> 157 | D6: =Februray!AH7 -> 157 | E6: =March!AH7 -> 181 | F6: =Aprail!AH7 -> 171 | G6: =May!AH7 -> 161 | H6: =June!AH7 -> 174 | I6: =July!AH7 -> 163 | J6: =August!AH7 -> 145 | K6: =September!AH7 -> 151 | L6: =October!AH7 | M6: =November!AH7 | N6: =December!AH7 | O6: =SUM(C6:N6) -> 1460 | P6: Branded | Q6: =SUM(C6:OFFSET(C6,0,$R$2-1)) -> 666 | S6: =AVERAGE(C6:N6) -> 162.22222
B7: Cetaphil | C7: ='Daily Sales(JAN)'!AH8 -> 167 | D7: =Februray!AH8 -> 166 | E7: =March!AH8 -> 166 | F7: =Aprail!AH8 -> 181 | G7: =May!AH8 -> 202 | H7: =June!AH8 -> 152 | I7: =July!AH8 -> 170 | J7: =August!AH8 -> 164 | K7: =September!AH8 -> 192 | L7: =October!AH8 | M7: =November!AH8 | N7: =December!AH8 | O7: =SUM(C7:N7) -> 1560 | P7: Branded | Q7: =SUM(C7:OFFSET(C7,0,$R$2-1)) -> 680 | S7: =AVERAGE(C7:N7) -> 173.33333
B8: Acetaminophen | C8: ='Daily Sales(JAN)'!AH9 -> 197 | D8: =Februray!AH9 -> 178 | E8: =March!AH9 -> 170 | F8: =Aprail!AH9 -> 174 | G8: =May!AH9 -> 160 | H8: =June!AH9 -> 164 | I8: =July!AH9 -> 194 | J8: =August!AH9 -> 180 | K8: =September!AH9 -> 170 | L8: =October!AH9 | M8: =November!AH9 | N8: =December!AH9 | O8: =SUM(C8:N8) -> 1587 | P8: Generic | Q8: =SUM(C8:OFFSET(C8,0,$R$2-1)) -> 719 | S8: =AVERAGE(C8:N8) -> 176.33333
B9: Ibuprofen | C9: ='Daily Sales(JAN)'!AH10 -> 199 | D9: =Februray!AH10 -> 159 | E9: =March!AH10 -> 177 | F9: =Aprail!AH10 -> 166 | G9: =May!AH10 -> 164 | H9: =June!AH10 -> 167 | I9: =July!AH10 -> 158 | J9: =August!AH10 -> 153 | K9: =September!AH10 -> 187 | L9: =October!AH10 | M9: =November!AH10 | N9: =December!AH10 | O9: =SUM(C9:N9) -> 1530 | P9: Generic | Q9: =SUM(C9:OFFSET(C9,0,$R$2-1)) -> 701 | S9: =AVERAGE(C9:N9) -> 170
B10: Aspirin | C10: ='Daily Sales(JAN)'!AH11 -> 147 | D10: =Februray!AH11 -> 152 | E10: =March!AH11 -> 179 | F10: =Aprail!AH11 -> 159 | G10: =May!AH11 -> 182 | H10: =June!AH11 -> 152 | I10: =July!AH11 -> 147 | J10: =August!AH11 -> 166 | K10: =September!AH11 -> 152 | L10: =October!AH11 | M10: =November!AH11 | N10: =December!AH11 | O10: =SUM(C10:N10) -> 1436 | P10: Generic | Q10: =SUM(C10:OFFSET(C10,0,$R$2-1)) -> 637 | S10: =AVERAGE(C10:N10) -> 159.55556
B11: Amoxicillin | C11: ='Daily Sales(JAN)'!AH12 -> 195 | D11: =Februray!AH12 -> 155 | E11: =March!AH12 -> 183 | F11: =Aprail!AH12 -> 155 | G11: =May!AH12 -> 196 | H11: =June!AH12 -> 167 | I11: =July!AH12 -> 167 | J11: =August!AH12 -> 151 | K11: =September!AH12 -> 146 | L11: =October!AH12 | M11: =November!AH12 | N11: =December!AH12 | O11: =SUM(C11:N11) -> 1515 | P11: Generic | Q11: =SUM(C11:OFFSET(C11,0,$R$2-1)) -> 688 | S11: =AVERAGE(C11:N11) -> 168.33333
B12: Ciprofloxacin | C12: ='Daily Sales(JAN)'!AH13 -> 156 | D12: =Februray!AH13 -> 180 | E12: =March!AH13 -> 183 | F12: =Aprail!AH13 -> 169 | G12: =May!AH13 -> 163 | H12: =June!AH13 -> 163 | I12: =July!AH13 -> 161 | J12: =August!AH13 -> 140 | K12: =September!AH13 -> 157 | L12: =October!AH13 | M12: =November!AH13 | N12: =December!AH13 | O12: =SUM(C12:N12) -> 1472 | P12: Generic | Q12: =SUM(C12:OFFSET(C12,0,$R$2-1)) -> 688 | S12: =AVERAGE(C12:N12) -> 163.55556
B13: Lisinopril | C13: ='Daily Sales(JAN)'!AH14 -> 158 | D13: =Februray!AH14 -> 156 | E13: =March!AH14 -> 166 | F13: =Aprail!AH14 -> 153 | G13: =May!AH14 -> 200 | H13: =June!AH14 -> 163 | I13: =July!AH14 -> 215 | J13: =August!AH14 -> 165 | K13: =September!AH14 -> 219 | L13: =October!AH14 | M13: =November!AH14 | N13: =December!AH14 | O13: =SUM(C13:N13) -> 1595 | P13: Generic | Q13: =SUM(C13:OFFSET(C13,0,$R$2-1)) -> 633 | S13: =AVERAGE(C13:N13) -> 177.22222
B14: Atorvastatin | C14: ='Daily Sales(JAN)'!AH15 -> 154 | D14: =Februray!AH15 -> 157 | E14: =March!AH15 -> 165 | F14: =Aprail!AH15 -> 183 | G14: =May!AH15 -> 148 | H14: =June!AH15 -> 145 | I14: =July!AH15 -> 173 | J14: =August!AH15 -> 189 | K14: =September!AH15 -> 148 | L14: =October!AH15 | M14: =November!AH15 | N14: =December!AH15 | O14: =SUM(C14:N14) -> 1462 | P14: Generic | Q14: =SUM(C14:OFFSET(C14,0,$R$2-1)) -> 659 | S14: =AVERAGE(C14:N14) -> 162.44444
... B56: Lamotrigine | C56: ='Daily Sales(JAN)'!AH57 -> 182 | D56: =Februray!AH57 -> 121 | E56: =March!AH57 -> 153 | F56: =Aprail!AH57 -> 187 | G56: =May!AH57 -> 180 | H56: =June!AH57 -> 137 | I56: =July!AH57 -> 174 | J56: =August!AH57 -> 162 | K56: =September!AH57 -> 153 | L56: =October!AH57 | M56: =November!AH57 | N56: =December!AH57 | O56: =SUM(C56:N56) -> 1449 | P56: Generic | Q56: =SUM(C56:OFFSET(C56,0,$R$2-1)) -> 643 | S56: =AVERAGE(C56:N56) -> 161

Sheet Daily Sales(JAN)
C1: =TEXT(C2,"DDD") -> Mon | D1: =TEXT(D2,"DDD") -> Tue | E1: =TEXT(E2,"DDD") -> Wed | F1: =TEXT(F2,"DDD") -> Thu | G1: =TEXT(G2,"DDD") -> Fri | H1: =TEXT(H2,"DDD") -> Sat | I1: =TEXT(I2,"DDD") -> Sun | J1: =TEXT(J2,"DDD") -> Mon | ... AG1: =TEXT(AG2,"DDD") -> Wed | AH1: Total Sales | AI1: Incoming price (Including GST) | AJ1: Sales price | AK1: Profit Margin | AL1: Total collection | AM1: Net collection | AO1: Month | AP1: January
B2: Product Name | C2: =IF(COLUMNS($C$2:C2)>DAY($AP$4),"",$AP$3+COLUMNS($C$2:C2)-1) -> 45292 | D2: =IF(COLUMNS($C$2:D2)>DAY($AP$4),"",$AP$3+COLUMNS($C$2:D2)-1) -> 45293 | E2: =IF(COLUMNS($C$2:E2)>DAY($AP$4),"",$AP$3+COLUMNS($C$2:E2)-1) -> 45294 | F2: =IF(COLUMNS($C$2:F2)>DAY($AP$4),"",$AP$3+COLUMNS($C$2:F2)-1) -> 45295 | G2: =IF(COLUMNS($C$2:G2)>DAY($AP$4),"",$AP$3+COLUMNS($C$2:G2)-1) -> 45296 | H2: =IF(COLUMNS($C$2:H2)>DAY($AP$4),"",$AP$3+COLUMNS($C$2:H2)-1) -> 45297 | I2: =IF(COLUMNS($C$2:I2)>DAY($AP$4),"",$AP$3+COLUMNS($C$2:I2)-1) -> 45298 | J2: =IF(COLUMNS($C$2:J2)>DAY($AP$4),"",$AP$3+COLUMNS($C$2:J2)-1) -> 45299 | ... AG2: =IF(COLUMNS($C$2:AG2)>DAY($AP$4),"",$AP$3+COLUMNS($C$2:AG2)-1) -> 45322 | AO2: Year | AP2: 2024
B3: Iodex | C3: =RANDBETWEEN(1,10) -> 1 | D3: =RANDBETWEEN(1,10) -> 8 | E3: =RANDBETWEEN(1,10) -> 10 | F3: =RANDBETWEEN(1,10) -> 2 | G3: =RANDBETWEEN(1,10) -> 7 | H3: =RANDBETWEEN(1,10) -> 10 | I3: =RANDBETWEEN(1,10) -> 6 | J3: =RANDBETWEEN(1,10) -> 8 | ... AG3: =RANDBETWEEN(1,10) -> 2 | AH3: =SUM($C3:$AG3) -> 179 | AI3: 40 | AJ3: 80 | AK3: =AJ3-AI3 -> 40 | AL3: =AJ3*AH3 -> 14320 | AM3: =AK3*AH3 -> 7160 | AO3: Starting Date | AP3: =DATE(AP2,MONTH(AP1&1),1) -> 45292
B4: Nimocet | C4: =RANDBETWEEN(1,10) -> 5 | D4: =RANDBETWEEN(1,10) -> 4 | E4: =RANDBETWEEN(1,10) -> 7 | F4: =RANDBETWEEN(1,10) -> 3 | G4: =RANDBETWEEN(1,10) -> 9 | H4: =RANDBETWEEN(1,10) -> 6 | I4: =RANDBETWEEN(1,10) -> 3 | J4: =RANDBETWEEN(1,10) -> 6 | ... AG4: =RANDBETWEEN(1,10) -> 1 | AH4: =SUM($C4:$AG4) -> 179 | AI4: 7 | AJ4: 15 | AK4: =AJ4-AI4 -> 8 | AL4: =AJ4*AH4 -> 2685 | AM4: =AK4*AH4 -> 1432 | AO4: Ending Date | AP4: =EOMONTH(AP3,0) -> 45322
B5: Paracetamol | C5: =RANDBETWEEN(1,10) -> 6 | D5: =RANDBETWEEN(1,10) -> 5 | E5: =RANDBETWEEN(1,10) -> 3 | F5: =RANDBETWEEN(1,10) -> 3 | G5: =RANDBETWEEN(1,10) -> 7 | H5: =RANDBETWEEN(1,10) -> 6 | I5: =RANDBETWEEN(1,10) -> 7 | J5: =RANDBETWEEN(1,10) -> 4 | ... AG5: =RANDBETWEEN(1,10) -> 2 | AH5: =SUM($C5:$AG5) -> 177 | AI5: 5 | AJ5: 10 | AK5: =AJ5-AI5 -> 5 | AL5: =AJ5*AH5 -> 1770 | AM5: =AK5*AH5 -> 885
B6: Monocef | C6: =RANDBETWEEN(1,10) -> 5 | D6: =RANDBETWEEN(1,10) -> 8 | E6: =RANDBETWEEN(1,10) -> 8 | F6: =RANDBETWEEN(1,10) -> 8 | G6: =RANDBETWEEN(1,10) -> 3 | H6: =RANDBETWEEN(1,10) -> 6 | I6: =RANDBETWEEN(1,10) -> 2 | J6: =RANDBETWEEN(1,10) -> 9 | ... AG6: =RANDBETWEEN(1,10) -> 3 | AH6: =SUM($C6:$AG6) -> 170 | AI6: 45 | AJ6: 80 | AK6: =AJ6-AI6 -> 35 | AL6: =AJ6*AH6 -> 13600 | AM6: =AK6*AH6 -> 5950
B7: Cyclopalm | C7: =RANDBETWEEN(1,10) -> 5 | D7: =RANDBETWEEN(1,10) -> 6 | E7: =RANDBETWEEN(1,10) -> 9 | F7: =RANDBETWEEN(1,10) -> 2 | G7: =RANDBETWEEN(1,10) -> 10 | H7: =RANDBETWEEN(1,10) -> 3 | I7: =RANDBETWEEN(1,10) -> 1 | J7: =RANDBETWEEN(1,10) -> 8 | ... AG7: =RANDBETWEEN(1,10) -> 1 | AH7: =SUM($C7:$AG7) -> 157 | AI7: 392 | AJ7: 420 | AK7: =AJ7-AI7 -> 28 | AL7: =AJ7*AH7 -> 65940 | AM7: =AK7*AH7 -> 4396 | AO7: Expanses
B8: Cetaphil | C8: =RANDBETWEEN(1,10) -> 6 | D8: =RANDBETWEEN(1,10) -> 2 | E8: =RANDBETWEEN(1,10) -> 2 | F8: =RANDBETWEEN(1,10) -> 10 | G8: =RANDBETWEEN(1,10) -> 9 | H8: =RANDBETWEEN(1,10) -> 4 | I8: =RANDBETWEEN(1,10) -> 8 | J8: =RANDBETWEEN(1,10) -> 3 | ... AG8: =RANDBETWEEN(1,10) -> 1 | AH8: =SUM($C8:$AG8) -> 167 | AI8: 86 | AJ8: 100 | AK8: =AJ8-AI8 -> 14 | AL8: =AJ8*AH8 -> 16700 | AM8: =AK8*AH8 -> 2338 | AO8: Employee Salary
B9: Acetaminophen | C9: =RANDBETWEEN(1,10) -> 1 | D9: =RANDBETWEEN(1,10) -> 4 | E9: =RANDBETWEEN(1,10) -> 1 | F9: =RANDBETWEEN(1,10) -> 4 | G9: =RANDBETWEEN(1,10) -> 1 | H9: =RANDBETWEEN(1,10) -> 9 | I9: =RANDBETWEEN(1,10) -> 5 | J9: =RANDBETWEEN(1,10) -> 9 | ... AG9: =RANDBETWEEN(1,10) -> 10 | AH9: =SUM($C9:$AG9) -> 197 | AI9: 271 | AJ9: 300 | AK9: =AJ9-AI9 -> 29 | AL9: =AJ9*AH9 -> 59100 | AM9: =AK9*AH9 -> 5713 | AO9: Kaishav(Owner) | AP9: ='Attendence (Jan)'!AL3 -> 50000
B10: Ibuprofen | C10: =RANDBETWEEN(1,10) -> 10 | D10: =RANDBETWEEN(1,10) -> 9 | E10: =RANDBETWEEN(1,10) -> 5 | F10: =RANDBETWEEN(1,10) -> 3 | G10: =RANDBETWEEN(1,10) -> 9 | H10: =RANDBETWEEN(1,10) -> 10 | I10: =RANDBETWEEN(1,10) -> 9 | J10: =RANDBETWEEN(1,10) -> 10 | ... AG10: =RANDBETWEEN(1,10) -> 10 | AH10: =SUM($C10:$AG10) -> 199 | AI10: 226 | AJ10: 250 | AK10: =AJ10-AI10 -> 24 | AL10: =AJ10*AH10 -> 49750 | AM10: =AK10*AH10 -> 4776 | AO10: Raman | AP10: ='Attendence (Jan)'!AL4 -> 14500
B11: Aspirin | C11: =RANDBETWEEN(1,10) -> 8 | D11: =RANDBETWEEN(1,10) -> 4 | E11: =RANDBETWEEN(1,10) -> 2 | F11: =RANDBETWEEN(1,10) -> 2 | G11: =RANDBETWEEN(1,10) -> 6 | H11: =RANDBETWEEN(1,10) -> 10 | I11: =RANDBETWEEN(1,10) -> 3 | J11: =RANDBETWEEN(1,10) -> 3 | ... AG11: =RANDBETWEEN(1,10) -> 10 | AH11: =SUM($C11:$AG11) -> 147 | AI11: 390 | AJ11: 450 | AK11: =AJ11-AI11 -> 60 | AL11: =AJ11*AH11 -> 66150 | AM11: =AK11*AH11 -> 8820 | AO11: Sohan | AP11: ='Attendence (Jan)'!AL5 -> 17400
B12: Amoxicillin | C12: =RANDBETWEEN(1,10) -> 7 | D12: =RANDBETWEEN(1,10) -> 7 | E12: =RANDBETWEEN(1,10) -> 10 | F12: =RANDBETWEEN(1,10) -> 7 | G12: =RANDBETWEEN(1,10) -> 5 | H12: =RANDBETWEEN(1,10) -> 8 | I12: =RANDBETWEEN(1,10) -> 3 | J12: =RANDBETWEEN(1,10) -> 9 | ... AG12: =RANDBETWEEN(1,10) -> 8 | AH12: =SUM($C12:$AG12) -> 195 | AI12: 379 | AJ12: 430 | AK12: =AJ12-AI12 -> 51 | AL12: =AJ12*AH12 -> 83850 | AM12: =AK12*AH12 -> 9945 | AO12: Tilak | AP12: ='Attendence (Jan)'!AL6 -> 9666.6667
B13: Ciprofloxacin | C13: =RANDBETWEEN(1,10) -> 4 | D13: =RANDBETWEEN(1,10) -> 10 | E13: =RANDBETWEEN(1,10) -> 1 | F13: =RANDBETWEEN(1,10) -> 1 | G13: =RANDBETWEEN(1,10) -> 1 | H13: =RANDBETWEEN(1,10) -> 6 | I13: =RANDBETWEEN(1,10) -> 9 | J13: =RANDBETWEEN(1,10) -> 2 | ... AG13: =RANDBETWEEN(1,10) -> 8 | AH13: =SUM($C13:$AG13) -> 156 | AI13: 368 | AJ13: 435 | AK13: =AJ13-AI13 -> 67 | AL13: =AJ13*AH13 -> 67860 | AM13: =AK13*AH13 -> 10452 | AO13: Bill to pay | AP13: 10000
B14: Lisinopril | C14: =RANDBETWEEN(1,10) -> 5 | D14: =RANDBETWEEN(1,10) -> 5 | E14: =RANDBETWEEN(1,10) -> 5 | F14: =RANDBETWEEN(1,10) -> 4 | G14: =RANDBETWEEN(1,10) -> 2 | H14: =RANDBETWEEN(1,10) -> 10 | I14: =RANDBETWEEN(1,10) -> 1 | J14: =RANDBETWEEN(1,10) -> 8 | ... AG14: =RANDBETWEEN(1,10) -> 5 | AH14: =SUM($C14:$AG14) -> 158 | AI14: 88 | AJ14: 99 | AK14: =AJ14-AI14 -> 11 | AL14: =AJ14*AH14 -> 15642 | AM14: =AK14*AH14 -> 1738 | AO14: other | AP14: 2000
B15: Atorvastatin | C15: =RANDBETWEEN(1,10) -> 6 | D15: =RANDBETWEEN(1,10) -> 8 | E15: =RANDBETWEEN(1,10) -> 3 | F15: =RANDBETWEEN(1,10) -> 10 | G15: =RANDBETWEEN(1,10) -> 4 | H15: =RANDBETWEEN(1,10) -> 6 | I15: =RANDBETWEEN(1,10) -> 7 | J15: =RANDBETWEEN(1,10) -> 1 | ... AG15: =RANDBETWEEN(1,10) -> 2 | AH15: =SUM($C15:$AG15) -> 154 | AI15: 391 | AJ15: 500 | AK15: =AJ15-AI15 -> 109 | AL15: =AJ15*AH15 -> 77000 | AM15: =AK15*AH15 -> 16786 | AO15: Net collection | AP15: =SUM(AM3:AM57) -> 293799
B16: Metformin | C16: =RANDBETWEEN(1,10) -> 7 | D16: =RANDBETWEEN(1,10) -> 1 | E16: =RANDBETWEEN(1,10) -> 1 | F16: =RANDBETWEEN(1,10) -> 6 | G16: =RANDBETWEEN(1,10) -> 9 | H16: =RANDBETWEEN(1,10) -> 3 | I16: =RANDBETWEEN(1,10) -> 1 | J16: =RANDBETWEEN(1,10) -> 1 | ... AG16: =RANDBETWEEN(1,10) -> 9 | AH16: =SUM($C16:$AG16) -> 183 | AI16: 261 | AJ16: 300 | AK16: =AJ16-AI16 -> 39 | AL16: =AJ16*AH16 -> 54900 | AM16: =AK16*AH16 -> 7137 | AO16: Net Income | AP16: =AP15-(AP9+AP10+AP11+AP12+AP13+AP14) -> 190232.33
B17: Simvastatin | C17: =RANDBETWEEN(1,10) -> 1 | D17: =RANDBETWEEN(1,10) -> 7 | E17: =RANDBETWEEN(1,10) -> 7 | F17: =RANDBETWEEN(1,10) -> 6 | G17: =RANDBETWEEN(1,10) -> 4 | H17: =RANDBETWEEN(1,10) -> 6 | I17: =RANDBETWEEN(1,10) -> 5 | J17: =RANDBETWEEN(1,10) -> 4 | ... AG17: =RANDBETWEEN(1,10) -> 4 | AH17: =SUM($C17:$AG17) -> 163 | AI17: 67 | AJ17: 99 | AK17: =AJ17-AI17 -> 32 | AL17: =AJ17*AH17 -> 16137 | AM17: =AK17*AH17 -> 5216
B18: Omeprazole | C18: =RANDBETWEEN(1,10) -> 9 | D18: =RANDBETWEEN(1,10) -> 10 | E18: =RANDBETWEEN(1,10) -> 1 | F18: =RANDBETWEEN(1,10) -> 4 | G18: =RANDBETWEEN(1,10) -> 7 | H18: =RANDBETWEEN(1,10) -> 5 | I18: =RANDBETWEEN(1,10) -> 9 | J18: =RANDBETWEEN(1,10) -> 10 | ... AG18: =RANDBETWEEN(1,10) -> 10 | AH18: =SUM($C18:$AG18) -> 187 | AI18: 138 | AJ18: 150 | AK18: =AJ18-AI18 -> 12 | AL18: =AJ18*AH18 -> 28050 | AM18: =AK18*AH18 -> 2244
B19: Clopidogrel | C19: =RANDBETWEEN(1,10) -> 6 | D19: =RANDBETWEEN(1,10) -> 2 | E19: =RANDBETWEEN(1,10) -> 3 | F19: =RANDBETWEEN(1,10) -> 9 | G19: =RANDBETWEEN(1,10) -> 7 | H19: =RANDBETWEEN(1,10) -> 8 | I19: =RANDBETWEEN(1,10) -> 7 | J19: =RANDBETWEEN(1,10) -> 7 | ... AG19: =RANDBETWEEN(1,10) -> 6 | AH19: =SUM($C19:$AG19) -> 157 | AI19: 60 | AJ19: 80 | AK19: =AJ19-AI19 -> 20 | AL19: =AJ19*AH19 -> 12560 | AM19: =AK19*AH19 -> 3140
B20: Metoprolol | C20: =RANDBETWEEN(1,10) -> 10 | D20: =RANDBETWEEN(1,10) -> 5 | E20: =RANDBETWEEN(1,10) -> 2 | F20: =RANDBETWEEN(1,10) -> 9 | G20: =RANDBETWEEN(1,10) -> 2 | H20: =RANDBETWEEN(1,10) -> 10 | I20: =RANDBETWEEN(1,10) -> 3 | J20: =RANDBETWEEN(1,10) -> 10 | ... AG20: =RANDBETWEEN(1,10) -> 7 | AH20: =SUM($C20:$AG20) -> 181 | AI20: 44 | AJ20: 50 | AK20: =AJ20-AI20 -> 6 | AL20: =AJ20*AH20 -> 9050 | AM20: =AK20*AH20 -> 1086
B21: Amlodipine | C21: =RANDBETWEEN(1,10) -> 8 | D21: =RANDBETWEEN(1,10) -> 9 | E21: =RANDBETWEEN(1,10) -> 1 | F21: =RANDBETWEEN(1,10) -> 1 | G21: =RANDBETWEEN(1,10) -> 7 | H21: =RANDBETWEEN(1,10) -> 5 | I21: =RANDBETWEEN(1,10) -> 7 | J21: =RANDBETWEEN(1,10) -> 9 | ... AG21: =RANDBETWEEN(1,10) -> 4 | AH21: =SUM($C21:$AG21) -> 179 | AI21: 308 | AJ21: 320 | AK21: =AJ21-AI21 -> 12 | AL21: =AJ21*AH21 -> 57280 | AM21: =AK21*AH21 -> 2148
B22: Alprazolam | C22: =RANDBETWEEN(1,10) -> 3 | D22: =RANDBETWEEN(1,10) -> 7 | E22: =RANDBETWEEN(1,10) -> 2 | F22: =RANDBETWEEN(1,10) -> 8 | G22: =RANDBETWEEN(1,10) -> 3 | H22: =RANDBETWEEN(1,10) -> 3 | I22: =RANDBETWEEN(1,10) -> 5 | J22: =RANDBETWEEN(1,10) -> 7 | ... AG22: =RANDBETWEEN(1,10) -> 5 | AH22: =SUM($C22:$AG22) -> 157 | AI22: 234 | AJ22: 250 | AK22: =AJ22-AI22 -> 16 | AL22: =AJ22*AH22 -> 39250 | AM22: =AK22*AH22 -> 2512
B23: Hydrocodone | C23: =RANDBETWEEN(1,10) -> 10 | D23: =RANDBETWEEN(1,10) -> 5 | E23: =RANDBETWEEN(1,10) -> 2 | F23: =RANDBETWEEN(1,10) -> 8 | G23: =RANDBETWEEN(1,10) -> 5 | H23: =RANDBETWEEN(1,10) -> 6 | I23: =RANDBETWEEN(1,10) -> 7 | J23: =RANDBETWEEN(1,10) -> 5 | ... AG23: =RANDBETWEEN(1,10) -> 5 | AH23: =SUM($C23:$AG23) -> 161 | AI23: 121 | AJ23: 140 | AK23: =AJ23-AI23 -> 19 | AL23: =AJ23*AH23 -> 22540 | AM23: =AK23*AH23 -> 3059
B24: Gabapentin | C24: =RANDBETWEEN(1,10) -> 4 | D24: =RANDBETWEEN(1,10) -> 3 | E24: =RANDBETWEEN(1,10) -> 6 | F24: =RANDBETWEEN(1,10) -> 10 | G24: =RANDBETWEEN(1,10) -> 9 | H24: =RANDBETWEEN(1,10) -> 7 | I24: =RANDBETWEEN(1,10) -> 6 | J24: =RANDBETWEEN(1,10) -> 9 | ... AG24: =RANDBETWEEN(1,10) -> 2 | AH24: =SUM($C24:$AG24) -> 159 | AI24: 350 | AJ24: 390 | AK24: =AJ24-AI24 -> 40 | AL24: =AJ24*AH24 -> 62010 | AM24: =AK24*AH24 -> 6360
B25: Levothyroxine | C25: =RANDBETWEEN(1,10) -> 7 | D25: =RANDBETWEEN(1,10) -> 8 | E25: =RANDBETWEEN(1,10) -> 9 | F25: =RANDBETWEEN(1,10) -> 6 | G25: =RANDBETWEEN(1,10) -> 4 | H25: =RANDBETWEEN(1,10) -> 2 | I25: =RANDBETWEEN(1,10) -> 9 | J25: =RANDBETWEEN(1,10) -> 5 | ... AG25: =RANDBETWEEN(1,10) -> 2 | AH25: =SUM($C25:$AG25) -> 191 | AI25: 211 | AJ25: 240 | AK25: =AJ25-AI25 -> 29 | AL25: =AJ25*AH25 -> 45840 | AM25: =AK25*AH25 -> 5539
B26: Sertraline | C26: =RANDBETWEEN(1,10) -> 9 | D26: =RANDBETWEEN(1,10) -> 5 | E26: =RANDBETWEEN(1,10) -> 2 | F26: =RANDBETWEEN(1,10) -> 6 | G26: =RANDBETWEEN(1,10) -> 9 | H26: =RANDBETWEEN(1,10) -> 3 | I26: =RANDBETWEEN(1,10) -> 1 | J26: =RANDBETWEEN(1,10) -> 10 | ... AG26: =RANDBETWEEN(1,10) -> 5 | AH26: =SUM($C26:$AG26) -> 180 | AI26: 247 | AJ26: 280 | AK26: =AJ26-AI26 -> 33 | AL26: =AJ26*AH26 -> 50400 | AM26: =AK26*AH26 -> 5940
B27: Azithromycin | C27: =RANDBETWEEN(1,10) -> 5 | D27: =RANDBETWEEN(1,10) -> 3 | E27: =RANDBETWEEN(1,10) -> 10 | F27: =RANDBETWEEN(1,10) -> 3 | G27: =RANDBETWEEN(1,10) -> 7 | H27: =RANDBETWEEN(1,10) -> 5 | I27: =RANDBETWEEN(1,10) -> 4 | J27: =RANDBETWEEN(1,10) -> 9 | ... AG27: =RANDBETWEEN(1,10) -> 3 | AH27: =SUM($C27:$AG27) -> 159 | AI27: 286 | AJ27: 320 | AK27: =AJ27-AI27 -> 34 | AL27: =AJ27*AH27 -> 50880 | AM27: =AK27*AH27 -> 5406
B28: Losartan | C28: =RANDBETWEEN(1,10) -> 9 | D28: =RANDBETWEEN(1,10) -> 6 | E28: =RANDBETWEEN(1,10) -> 1 | F28: =RANDBETWEEN(1,10) -> 6 | G28: =RANDBETWEEN(1,10) -> 2 | H28: =RANDBETWEEN(1,10) -> 1 | I28: =RANDBETWEEN(1,10) -> 1 | J28: =RANDBETWEEN(1,10) -> 9 | ... AG28: =RANDBETWEEN(1,10) -> 5 | AH28: =SUM($C28:$AG28) -> 161 | AI28: 67 | AJ28: 80 | AK28: =AJ28-AI28 -> 13 | AL28: =AJ28*AH28 -> 12880 | AM28: =AK28*AH28 -> 2093
... B57: Lamotrigine | C57: =RANDBETWEEN(1,10) -> 9 | D57: =RANDBETWEEN(1,10) -> 8 | E57: =RANDBETWEEN(1,10) -> 1 | F57: =RANDBETWEEN(1,10) -> 6 | G57: =RANDBETWEEN(1,10) -> 2 | H57: =RANDBETWEEN(1,10) -> 10 | I57: =RANDBETWEEN(1,10) -> 5 | J57: =RANDBETWEEN(1,10) -> 6 | ... AG57: =RANDBETWEEN(1,10) -> 4 | AH57: =SUM($C57:$AG57) -> 182 | AI57: 340 | AJ57: 380 | AK57: =AJ57-AI57 -> 40 | AL57: =AJ57*AH57 -> 69160 | AM57: =AK57*AH57 -> 7280

Sheet Februray
C1: =TEXT(C2,"DDD") -> Thu | D1: =TEXT(D2,"DDD") -> Fri | E1: =TEXT(E2,"DDD") -> Sat | F1: =TEXT(F2,"DDD") -> Sun | G1: =TEXT(G2,"DDD") -> Mon | H1: =TEXT(H2,"DDD") -> Tue | I1: =TEXT(I2,"DDD") -> Wed | J1: =TEXT(J2,"DDD") -> Thu | ... AG1: =TEXT(AG2,"DDD") | AH1: Total Sales | AI1: Incoming price (Including GST) | AJ1: Sales price | AK1: Profit Margin | AL1: Total collection | AM1: Net collection | AO1: Month | AP1: February
B2: Product Name | C2: =IF(COLUMNS($C$2:C2)>DAY($AP$4),"",$AP$3+COLUMNS($C$2:C2)-1) -> 45323 | D2: =IF(COLUMNS($C$2:D2)>DAY($AP$4),"",$AP$3+COLUMNS($C$2:D2)-1) -> 45324 | E2: =IF(COLUMNS($C$2:E2)>DAY($AP$4),"",$AP$3+COLUMNS($C$2:E2)-1) -> 45325 | F2: =IF(COLUMNS($C$2:F2)>DAY($AP$4),"",$AP$3+COLUMNS($C$2:F2)-1) -> 45326 | G2: =IF(COLUMNS($C$2:G2)>DAY($AP$4),"",$AP$3+COLUMNS($C$2:G2)-1) -> 45327 | H2: =IF(COLUMNS($C$2:H2)>DAY($AP$4),"",$AP$3+COLUMNS($C$2:H2)-1) -> 45328 | I2: =IF(COLUMNS($C$2:I2)>DAY($AP$4),"",$AP$3+COLUMNS($C$2:I2)-1) -> 45329 | J2: =IF(COLUMNS($C$2:J2)>DAY($AP$4),"",$AP$3+COLUMNS($C$2:J2)-1) -> 45330 | ... AG2: =IF(COLUMNS($C$2:AG2)>DAY($AP$4),"",$AP$3+COLUMNS($C$2:AG2)-1) | AO2: Year | AP2: 2024
B3: Iodex | C3: =RANDBETWEEN(1,10) -> 3 | D3: =RANDBETWEEN(1,10) -> 9 | E3: =RANDBETWEEN(1,10) -> 7 | F3: =RANDBETWEEN(1,10) -> 10 | G3: =RANDBETWEEN(1,10) -> 9 | H3: =RANDBETWEEN(1,10) -> 5 | I3: =RANDBETWEEN(1,10) -> 3 | J3: =RANDBETWEEN(1,10) -> 2 | ... AE3: =RANDBETWEEN(1,10) -> 6 | AH3: =SUM($C3:$AG3) -> 177 | AI3: 40 | AJ3: 80 | AK3: =AJ3-AI3 -> 40 | AL3: =AJ3*AH3 -> 14160 | AM3: =AK3*AH3 -> 7080 | AO3: Starting Date | AP3: =DATE(AP2,MONTH(AP1&1),1) -> 45323
B4: Nimocet | C4: =RANDBETWEEN(1,10) -> 3 | D4: =RANDBETWEEN(1,10) -> 4 | E4: =RANDBETWEEN(1,10) -> 8 | F4: =RANDBETWEEN(1,10) -> 8 | G4: =RANDBETWEEN(1,10) -> 4 | H4: =RANDBETWEEN(1,10) -> 8 | I4: =RANDBETWEEN(1,10) -> 4 | J4: =RANDBETWEEN(1,10) -> 8 | ... AE4: =RANDBETWEEN(1,10) -> 6 | AH4: =SUM($C4:$AG4) -> 203 | AI4: 7 | AJ4: 15 | AK4: =AJ4-AI4 -> 8 | AL4: =AJ4*AH4 -> 3045 | AM4: =AK4*AH4 -> 1624 | AO4: Ending Date | AP4: =EOMONTH(AP3,0) -> 45351
B5: Paracetamol | C5: =RANDBETWEEN(1,10) -> 2 | D5: =RANDBETWEEN(1,10) -> 3 | E5: =RANDBETWEEN(1,10) -> 3 | F5: =RANDBETWEEN(1,10) -> 10 | G5: =RANDBETWEEN(1,10) -> 1 | H5: =RANDBETWEEN(1,10) -> 3 | I5: =RANDBETWEEN(1,10) -> 6 | J5: =RANDBETWEEN(1,10) -> 1 | ... AE5: =RANDBETWEEN(1,10) -> 4 | AH5: =SUM($C5:$AG5) -> 161 | AI5: 5 | AJ5: 10 | AK5: =AJ5-AI5 -> 5 | AL5: =AJ5*AH5 -> 1610 | AM5: =AK5*AH5 -> 805
B6: Monocef | C6: =RANDBETWEEN(1,10) -> 5 | D6: =RANDBETWEEN(1,10) -> 2 | E6: =RANDBETWEEN(1,10) -> 1 | F6: =RANDBETWEEN(1,10) -> 3 | G6: =RANDBETWEEN(1,10) -> 3 | H6: =RANDBETWEEN(1,10) -> 5 | I6: =RANDBETWEEN(1,10) -> 8 | J6: =RANDBETWEEN(1,10) -> 6 | ... AE6: =RANDBETWEEN(1,10) -> 9 | AH6: =SUM($C6:$AG6) -> 142 | AI6: 45 | AJ6: 80 | AK6: =AJ6-AI6 -> 35 | AL6: =AJ6*AH6 -> 11360 | AM6: =AK6*AH6 -> 4970
B7: Cyclopalm | C7: =RANDBETWEEN(1,10) -> 3 | D7: =RANDBETWEEN(1,10) -> 2 | E7: =RANDBETWEEN(1,10) -> 6 | F7: =RANDBETWEEN(1,10) -> 3 | G7: =RANDBETWEEN(1,10) -> 4 | H7: =RANDBETWEEN(1,10) -> 6 | I7: =RANDBETWEEN(1,10) -> 6 | J7: =RANDBETWEEN(1,10) -> 5 | ... AE7: =RANDBETWEEN(1,10) -> 4 | AH7: =SUM($C7:$AG7) -> 157 | AI7: 392 | AJ7: 420 | AK7: =AJ7-AI7 -> 28 | AL7: =AJ7*AH7 -> 65940 | AM7: =AK7*AH7 -> 4396 | AO7: Expanses
B8: Cetaphil | C8: =RANDBETWEEN(1,10) -> 3 | D8: =RANDBETWEEN(1,10) -> 10 | E8: =RANDBETWEEN(1,10) -> 10 | F8: =RANDBETWEEN(1,10) -> 4 | G8: =RANDBETWEEN(1,10) -> 2 | H8: =RANDBETWEEN(1,10) -> 9 | I8: =RANDBETWEEN(1,10) -> 8 | J8: =RANDBETWEEN(1,10) -> 4 | ... AE8: =RANDBETWEEN(1,10) -> 8 | AH8: =SUM($C8:$AG8) -> 166 | AI8: 86 | AJ8: 100 | AK8: =AJ8-AI8 -> 14 | AL8: =AJ8*AH8 -> 16600 | AM8: =AK8*AH8 -> 2324 | AO8: Employee Salary
B9: Acetaminophen | C9: =RANDBETWEEN(1,10) -> 1 | D9: =RANDBETWEEN(1,10) -> 10 | E9: =RANDBETWEEN(1,10) -> 9 | F9: =RANDBETWEEN(1,10) -> 9 | G9: =RANDBETWEEN(1,10) -> 9 | H9: =RANDBETWEEN(1,10) -> 3 | I9: =RANDBETWEEN(1,10) -> 4 | J9: =RANDBETWEEN(1,10) -> 1 | ... AE9: =RANDBETWEEN(1,10) -> 10 | AH9: =SUM($C9:$AG9) -> 178 | AI9: 271 | AJ9: 300 | AK9: =AJ9-AI9 -> 29 | AL9: =AJ9*AH9 -> 53400 | AM9: =AK9*AH9 -> 5162 | AO9: Kaishav(Owner) | AP9: ='Attendence (Feb)'!AL3 -> 46666.667
B10: Ibuprofen | C10: =RANDBETWEEN(1,10) -> 9 | D10: =RANDBETWEEN(1,10) -> 10 | E10: =RANDBETWEEN(1,10) -> 1 | F10: =RANDBETWEEN(1,10) -> 10 | G10: =RANDBETWEEN(1,10) -> 2 | H10: =RANDBETWEEN(1,10) -> 1 | I10: =RANDBETWEEN(1,10) -> 9 | J10: =RANDBETWEEN(1,10) -> 5 | ... AE10: =RANDBETWEEN(1,10) -> 5 | AH10: =SUM($C10:$AG10) -> 159 | AI10: 226 | AJ10: 250 | AK10: =AJ10-AI10 -> 24 | AL10: =AJ10*AH10 -> 39750 | AM10: =AK10*AH10 -> 3816 | AO10: Raman | AP10: ='Attendence (Feb)'!AL4 -> 13500
B11: Aspirin | C11: =RANDBETWEEN(1,10) -> 8 | D11: =RANDBETWEEN(1,10) -> 2 | E11: =RANDBETWEEN(1,10) -> 10 | F11: =RANDBETWEEN(1,10) -> 1 | G11: =RANDBETWEEN(1,10) -> 2 | H11: =RANDBETWEEN(1,10) -> 3 | I11: =RANDBETWEEN(1,10) -> 9 | J11: =RANDBETWEEN(1,10) -> 9 | ... AE11: =RANDBETWEEN(1,10) -> 5 | AH11: =SUM($C11:$AG11) -> 152 | AI11: 390 | AJ11: 450 | AK11: =AJ11-AI11 -> 60 | AL11: =AJ11*AH11 -> 68400 | AM11: =AK11*AH11 -> 9120 | AO11: Sohan | AP11: ='Attendence (Feb)'!AL5 -> 16800
B12: Amoxicillin | C12: =RANDBETWEEN(1,10) -> 8 | D12: =RANDBETWEEN(1,10) -> 4 | E12: =RANDBETWEEN(1,10) -> 8 | F12: =RANDBETWEEN(1,10) -> 1 | G12: =RANDBETWEEN(1,10) -> 10 | H12: =RANDBETWEEN(1,10) -> 4 | I12: =RANDBETWEEN(1,10) -> 8 | J12: =RANDBETWEEN(1,10) -> 7 | ... AE12: =RANDBETWEEN(1,10) -> 4 | AH12: =SUM($C12:$AG12) -> 155 | AI12: 379 | AJ12: 430 | AK12: =AJ12-AI12 -> 51 | AL12: =AJ12*AH12 -> 66650 | AM12: =AK12*AH12 -> 7905 | AO12: Tilak | AP12: ='Attendence (Feb)'!AL6 -> 9000
B13: Ciprofloxacin | C13: =RANDBETWEEN(1,10) -> 5 | D13: =RANDBETWEEN(1,10) -> 9 | E13: =RANDBETWEEN(1,10) -> 9 | F13: =RANDBETWEEN(1,10) -> 8 | G13: =RANDBETWEEN(1,10) -> 4 | H13: =RANDBETWEEN(1,10) -> 9 | I13: =RANDBETWEEN(1,10) -> 10 | J13: =RANDBETWEEN(1,10) -> 1 | ... AE13: =RANDBETWEEN(1,10) -> 3 | AH13: =SUM($C13:$AG13) -> 180 | AI13: 368 | AJ13: 435 | AK13: =AJ13-AI13 -> 67 | AL13: =AJ13*AH13 -> 78300 | AM13: =AK13*AH13 -> 12060 | AO13: Bill to pay | AP13: 10000
B14: Lisinopril | C14: =RANDBETWEEN(1,10) -> 9 | D14: =RANDBETWEEN(1,10) -> 2 | E14: =RANDBETWEEN(1,10) -> 3 | F14: =RANDBETWEEN(1,10) -> 4 | G14: =RANDBETWEEN(1,10) -> 1 | H14: =RANDBETWEEN(1,10) -> 1 | I14: =RANDBETWEEN(1,10) -> 9 | J14: =RANDBETWEEN(1,10) -> 4 | ... AE14: =RANDBETWEEN(1,10) -> 10 | AH14: =SUM($C14:$AG14) -> 156 | AI14: 88 | AJ14: 99 | AK14: =AJ14-AI14 -> 11 | AL14: =AJ14*AH14 -> 15444 | AM14: =AK14*AH14 -> 1716 | AO14: other | AP14: 2000
B15: Atorvastatin | C15: =RANDBETWEEN(1,10) -> 9 | D15: =RANDBETWEEN(1,10) -> 8 | E15: =RANDBETWEEN(1,10) -> 9 | F15: =RANDBETWEEN(1,10) -> 7 | G15: =RANDBETWEEN(1,10) -> 3 | H15: =RANDBETWEEN(1,10) -> 1 | I15: =RANDBETWEEN(1,10) -> 4 | J15: =RANDBETWEEN(1,10) -> 5 | ... AE15: =RANDBETWEEN(1,10) -> 4 | AH15: =SUM($C15:$AG15) -> 157 | AI15: 391 | AJ15: 500 | AK15: =AJ15-AI15 -> 109 | AL15: =AJ15*AH15 -> 78500 | AM15: =AK15*AH15 -> 17113 | AO15: Net collection | AP15: =SUM(AM3:AM57) -> 280433
B16: Metformin | C16: =RANDBETWEEN(1,10) -> 7 | D16: =RANDBETWEEN(1,10) -> 5 | E16: =RANDBETWEEN(1,10) -> 1 | F16: =RANDBETWEEN(1,10) -> 6 | G16: =RANDBETWEEN(1,10) -> 7 | H16: =RANDBETWEEN(1,10) -> 8 | I16: =RANDBETWEEN(1,10) -> 8 | J16: =RANDBETWEEN(1,10) -> 9 | ... AE16: =RANDBETWEEN(1,10) -> 9 | AH16: =SUM($C16:$AG16) -> 147 | AI16: 261 | AJ16: 300 | AK16: =AJ16-AI16 -> 39 | AL16: =AJ16*AH16 -> 44100 | AM16: =AK16*AH16 -> 5733 | AO16: Net Income | AP16: =AP15-(AP9+AP10+AP11+AP12+AP13+AP14) -> 182466.33
B17: Simvastatin | C17: =RANDBETWEEN(1,10) -> 3 | D17: =RANDBETWEEN(1,10) -> 3 | E17: =RANDBETWEEN(1,10) -> 5 | F17: =RANDBETWEEN(1,10) -> 1 | G17: =RANDBETWEEN(1,10) -> 3 | H17: =RANDBETWEEN(1,10) -> 3 | I17: =RANDBETWEEN(1,10) -> 1 | J17: =RANDBETWEEN(1,10) -> 7 | ... AE17: =RANDBETWEEN(1,10) -> 1 | AH17: =SUM($C17:$AG17) -> 148 | AI17: 67 | AJ17: 99 | AK17: =AJ17-AI17 -> 32 | AL17: =AJ17*AH17 -> 14652 | AM17: =AK17*AH17 -> 4736
B18: Omeprazole | C18: =RANDBETWEEN(1,10) -> 3 | D18: =RANDBETWEEN(1,10) -> 2 | E18: =RANDBETWEEN(1,10) -> 2 | F18: =RANDBETWEEN(1,10) -> 3 | G18: =RANDBETWEEN(1,10) -> 1 | H18: =RANDBETWEEN(1,10) -> 10 | I18: =RANDBETWEEN(1,10) -> 3 | J18: =RANDBETWEEN(1,10) -> 4 | ... AE18: =RANDBETWEEN(1,10) -> 3 | AH18: =SUM($C18:$AG18) -> 140 | AI18: 138 | AJ18: 150 | AK18: =AJ18-AI18 -> 12 | AL18: =AJ18*AH18 -> 21000 | AM18: =AK18*AH18 -> 1680
B19: Clopidogrel | C19: =RANDBETWEEN(1,10) -> 4 | D19: =RANDBETWEEN(1,10) -> 8 | E19: =RANDBETWEEN(1,10) -> 5 | F19: =RANDBETWEEN(1,10) -> 7 | G19: =RANDBETWEEN(1,10) -> 3 | H19: =RANDBETWEEN(1,10) -> 9 | I19: =RANDBETWEEN(1,10) -> 9 | J19: =RANDBETWEEN(1,10) -> 3 | ... AE19: =RANDBETWEEN(1,10) -> 9 | AH19: =SUM($C19:$AG19) -> 176 | AI19: 60 | AJ19: 80 | AK19: =AJ19-AI19 -> 20 | AL19: =AJ19*AH19 -> 14080 | AM19: =AK19*AH19 -> 3520
B20: Metoprolol | C20: =RANDBETWEEN(1,10) -> 10 | D20: =RANDBETWEEN(1,10) -> 4 | E20: =RANDBETWEEN(1,10) -> 5 | F20: =RANDBETWEEN(1,10) -> 1 | G20: =RANDBETWEEN(1,10) -> 8 | H20: =RANDBETWEEN(1,10) -> 10 | I20: =RANDBETWEEN(1,10) -> 1 | J20: =RANDBETWEEN(1,10) -> 8 | ... AE20: =RANDBETWEEN(1,10) -> 6 | AH20: =SUM($C20:$AG20) -> 167 | AI20: 44 | AJ20: 50 | AK20: =AJ20-AI20 -> 6 | AL20: =AJ20*AH20 -> 8350 | AM20: =AK20*AH20 -> 1002
B21: Amlodipine | C21: =RANDBETWEEN(1,10) -> 9 | D21: =RANDBETWEEN(1,10) -> 6 | E21: =RANDBETWEEN(1,10) -> 2 | F21: =RANDBETWEEN(1,10) -> 3 | G21: =RANDBETWEEN(1,10) -> 4 | H21: =RANDBETWEEN(1,10) -> 1 | I21: =RANDBETWEEN(1,10) -> 7 | J21: =RANDBETWEEN(1,10) -> 5 | ... AE21: =RANDBETWEEN(1,10) -> 3 | AH21: =SUM($C21:$AG21) -> 147 | AI21: 308 | AJ21: 320 | AK21: =AJ21-AI21 -> 12 | AL21: =AJ21*AH21 -> 47040 | AM21: =AK21*AH21 -> 1764
B22: Alprazolam | C22: =RANDBETWEEN(1,10) -> 7 | D22: =RANDBETWEEN(1,10) -> 5 | E22: =RANDBETWEEN(1,10) -> 9 | F22: =RANDBETWEEN(1,10) -> 2 | G22: =RANDBETWEEN(1,10) -> 6 | H22: =RANDBETWEEN(1,10) -> 2 | I22: =RANDBETWEEN(1,10) -> 5 | J22: =RANDBETWEEN(1,10) -> 9 | ... AE22: =RANDBETWEEN(1,10) -> 5 | AH22: =SUM($C22:$AG22) -> 174 | AI22: 234 | AJ22: 250 | AK22: =AJ22-AI22 -> 16 | AL22: =AJ22*AH22 -> 43500 | AM22: =AK22*AH22 -> 2784
B23: Hydrocodone | C23: =RANDBETWEEN(1,10) -> 8 | D23: =RANDBETWEEN(1,10) -> 5 | E23: =RANDBETWEEN(1,10) -> 2 | F23: =RANDBETWEEN(1,10) -> 10 | G23: =RANDBETWEEN(1,10) -> 6 | H23: =RANDBETWEEN(1,10) -> 3 | I23: =RANDBETWEEN(1,10) -> 2 | J23: =RANDBETWEEN(1,10) -> 5 | ... AE23: =RANDBETWEEN(1,10) -> 9 | AH23: =SUM($C23:$AG23) -> 161 | AI23: 121 | AJ23: 140 | AK23: =AJ23-AI23 -> 19 | AL23: =AJ23*AH23 -> 22540 | AM23: =AK23*AH23 -> 3059
B24: Gabapentin | C24: =RANDBETWEEN(1,10) -> 2 | D24: =RANDBETWEEN(1,10) -> 7 | E24: =RANDBETWEEN(1,10) -> 8 | F24: =RANDBETWEEN(1,10) -> 7 | G24: =RANDBETWEEN(1,10) -> 9 | H24: =RANDBETWEEN(1,10) -> 9 | I24: =RANDBETWEEN(1,10) -> 1 | J24: =RANDBETWEEN(1,10) -> 4 | ... AE24: =RANDBETWEEN(1,10) -> 1 | AH24: =SUM($C24:$AG24) -> 124 | AI24: 350 | AJ24: 390 | AK24: =AJ24-AI24 -> 40 | AL24: =AJ24*AH24 -> 48360 | AM24: =AK24*AH24 -> 4960
B25: Levothyroxine | C25: =RANDBETWEEN(1,10) -> 8 | D25: =RANDBETWEEN(1,10) -> 8 | E25: =RANDBETWEEN(1,10) -> 6 | F25: =RANDBETWEEN(1,10) -> 2 | G25: =RANDBETWEEN(1,10) -> 5 | H25: =RANDBETWEEN(1,10) -> 2 | I25: =RANDBETWEEN(1,10) -> 5 | J25: =RANDBETWEEN(1,10) -> 2 | ... AE25: =RANDBETWEEN(1,10) -> 5 | AH25: =SUM($C25:$AG25) -> 160 | AI25: 211 | AJ25: 240 | AK25: =AJ25-AI25 -> 29 | AL25: =AJ25*AH25 -> 38400 | AM25: =AK25*AH25 -> 4640
B26: Sertraline | C26: =RANDBETWEEN(1,10) -> 4 | D26: =RANDBETWEEN(1,10) -> 1 | E26: =RANDBETWEEN(1,10) -> 9 | F26: =RANDBETWEEN(1,10) -> 9 | G26: =RANDBETWEEN(1,10) -> 5 | H26: =RANDBETWEEN(1,10) -> 10 | I26: =RANDBETWEEN(1,10) -> 2 | J26: =RANDBETWEEN(1,10) -> 9 | ... AE26: =RANDBETWEEN(1,10) -> 2 | AH26: =SUM($C26:$AG26) -> 159 | AI26: 247 | AJ26: 280 | AK26: =AJ26-AI26 -> 33 | AL26: =AJ26*AH26 -> 44520 | AM26: =AK26*AH26 -> 5247
B27: Azithromycin | C27: =RANDBETWEEN(1,10) -> 4 | D27: =RANDBETWEEN(1,10) -> 2 | E27: =RANDBETWEEN(1,10) -> 7 | F27: =RANDBETWEEN(1,10) -> 4 | G27: =RANDBETWEEN(1,10) -> 5 | H27: =RANDBETWEEN(1,10) -> 10 | I27: =RANDBETWEEN(1,10) -> 3 | J27: =RANDBETWEEN(1,10) -> 2 | ... AE27: =RANDBETWEEN(1,10) -> 10 | AH27: =SUM($C27:$AG27) -> 179 | AI27: 286 | AJ27: 320 | AK27: =AJ27-AI27 -> 34 | AL27: =AJ27*AH27 -> 57280 | AM27: =AK27*AH27 -> 6086
B28: Losartan | C28: =RANDBETWEEN(1,10) -> 4 | D28: =RANDBETWEEN(1,10) -> 1 | E28: =RANDBETWEEN(1,10) -> 7 | F28: =RANDBETWEEN(1,10) -> 7 | G28: =RANDBETWEEN(1,10) -> 1 | H28: =RANDBETWEEN(1,10) -> 6 | I28: =RANDBETWEEN(1,10) -> 8 | J28: =RANDBETWEEN(1,10) -> 7 | ... AE28: =RANDBETWEEN(1,10) -> 9 | AH28: =SUM($C28:$AG28) -> 178 | AI28: 67 | AJ28: 80 | AK28: =AJ28-AI28 -> 13 | AL28: =AJ28*AH28 -> 14240 | AM28: =AK28*AH28 -> 2314
... B57: Lamotrigine | C57: =RANDBETWEEN(1,10) -> 8 | D57: =RANDBETWEEN(1,10) -> 1 | E57: =RANDBETWEEN(1,10) -> 3 | F57: =RANDBETWEEN(1,10) -> 6 | G57: =RANDBETWEEN(1,10) -> 4 | H57: =RANDBETWEEN(1,10) -> 3 | I57: =RANDBETWEEN(1,10) -> 4 | J57: =RANDBETWEEN(1,10) -> 4 | ... AE57: =RANDBETWEEN(1,10) -> 4 | AH57: =SUM($C57:$AG57) -> 121 | AI57: 340 | AJ57: 380 | AK57: =AJ57-AI57 -> 40 | AL57: =AJ57*AH57 -> 45980 | AM57: =AK57*AH57 -> 4840

Sheet March
C1: =TEXT(C2,"DDD") -> Fri | D1: =TEXT(D2,"DDD") -> Sat | E1: =TEXT(E2,"DDD") -> Sun | F1: =TEXT(F2,"DDD") -> Mon | G1: =TEXT(G2,"DDD") -> Tue | H1: =TEXT(H2,"DDD") -> Wed | I1: =TEXT(I2,"DDD") -> Thu | J1: =TEXT(J2,"DDD") -> Fri | ... AG1: =TEXT(AG2,"DDD") -> Sun | AH1: Total Sales | AI1: Incoming price (Including GST) | AJ1: Sales price | AK1: Profit Margin | AL1: Total collection | AM1: Net collection | AO1: Month | AP1: March
B2: Product Name | C2: =IF(COLUMNS($C$2:C2)>DAY($AP$4),"",$AP$3+COLUMNS($C$2:C2)-1) -> 45352 | D2: =IF(COLUMNS($C$2:D2)>DAY($AP$4),"",$AP$3+COLUMNS($C$2:D2)-1) -> 45353 | E2: =IF(COLUMNS($C$2:E2)>DAY($AP$4),"",$AP$3+COLUMNS($C$2:E2)-1) -> 45354 | F2: =IF(COLUMNS($C$2:F2)>DAY($AP$4),"",$AP$3+COLUMNS($C$2:F2)-1) -> 45355 | G2: =IF(COLUMNS($C$2:G2)>DAY($AP$4),"",$AP$3+COLUMNS($C$2:G2)-1) -> 45356 | H2: =IF(COLUMNS($C$2:H2)>DAY($AP$4),"",$AP$3+COLUMNS($C$2:H2)-1) -> 45357 | I2: =IF(COLUMNS($C$2:I2)>DAY($AP$4),"",$AP$3+COLUMNS($C$2:I2)-1) -> 45358 | J2: =IF(COLUMNS($C$2:J2)>DAY($AP$4),"",$AP$3+COLUMNS($C$2:J2)-1) -> 45359 | ... AG2: =IF(COLUMNS($C$2:AG2)>DAY($AP$4),"",$AP$3+COLUMNS($C$2:AG2)-1) -> 45382 | AO2: Year | AP2: 2024
B3: Iodex | C3: =RANDBETWEEN(1,10) -> 3 | D3: =RANDBETWEEN(1,10) -> 3 | E3: =RANDBETWEEN(1,10) -> 1 | F3: =RANDBETWEEN(1,10) -> 1 | G3: =RANDBETWEEN(1,10) -> 5 | H3: =RANDBETWEEN(1,10) -> 7 | I3: =RANDBETWEEN(1,10) -> 7 | J3: =RANDBETWEEN(1,10) -> 10 | ... AG3: =RANDBETWEEN(1,10) -> 6 | AH3: =IF(SUM($C3:$AG3)>0,SUM($C3:$AG3),"") -> 166 | AI3: 40 | AJ3: 80 | AK3: =AJ3-AI3 -> 40 | AL3: =AJ3*AH3 -> 13280 | AM3: =AK3*AH3 -> 6640 | AO3: Starting Date | AP3: =DATE(AP2,MONTH(AP1&1),1) -> 45352
B4: Nimocet | C4: =RANDBETWEEN(1,10) -> 5 | D4: =RANDBETWEEN(1,10) -> 2 | E4: =RANDBETWEEN(1,10) -> 3 | F4: =RANDBETWEEN(1,10) -> 3 | G4: =RANDBETWEEN(1,10) -> 1 | H4: =RANDBETWEEN(1,10) -> 6 | I4: =RANDBETWEEN(1,10) -> 9 | J4: =RANDBETWEEN(1,10) -> 6 | ... AG4: =RANDBETWEEN(1,10) -> 4 | AH4: =IF(SUM($C4:$AG4)>0,SUM($C4:$AG4),"") -> 163 | AI4: 7 | AJ4: 15 | AK4: =AJ4-AI4 -> 8 | AL4: =AJ4*AH4 -> 2445 | AM4: =AK4*AH4 -> 1304 | AO4: Ending Date | AP4: =EOMONTH(AP3,0) -> 45382
B5: Paracetamol | C5: =RANDBETWEEN(1,10) -> 3 | D5: =RANDBETWEEN(1,10) -> 9 | E5: =RANDBETWEEN(1,10) -> 3 | F5: =RANDBETWEEN(1,10) -> 10 | G5: =RANDBETWEEN(1,10) -> 3 | H5: =RANDBETWEEN(1,10) -> 7 | I5: =RANDBETWEEN(1,10) -> 4 | J5: =RANDBETWEEN(1,10) -> 9 | ... AG5: =RANDBETWEEN(1,10) -> 9 | AH5: =IF(SUM($C5:$AG5)>0,SUM($C5:$AG5),"") -> 182 | AI5: 5 | AJ5: 10 | AK5: =AJ5-AI5 -> 5 | AL5: =AJ5*AH5 -> 1820 | AM5: =AK5*AH5 -> 910
B6: Monocef | C6: =RANDBETWEEN(1,10) -> 3 | D6: =RANDBETWEEN(1,10) -> 2 | E6: =RANDBETWEEN(1,10) -> 10 | F6: =RANDBETWEEN(1,10) -> 9 | G6: =RANDBETWEEN(1,10) -> 9 | H6: =RANDBETWEEN(1,10) -> 9 | I6: =RANDBETWEEN(1,10) -> 1 | J6: =RANDBETWEEN(1,10) -> 9 | ... AG6: =RANDBETWEEN(1,10) -> 4 | AH6: =IF(SUM($C6:$AG6)>0,SUM($C6:$AG6),"") -> 182 | AI6: 45 | AJ6: 80 | AK6: =AJ6-AI6 -> 35 | AL6: =AJ6*AH6 -> 14560 | AM6: =AK6*AH6 -> 6370
B7: Cyclopalm | C7: =RANDBETWEEN(1,10) -> 4 | D7: =RANDBETWEEN(1,10) -> 5 | E7: =RANDBETWEEN(1,10) -> 10 | F7: =RANDBETWEEN(1,10) -> 6 | G7: =RANDBETWEEN(1,10) -> 3 | H7: =RANDBETWEEN(1,10) -> 2 | I7: =RANDBETWEEN(1,10) -> 5 | J7: =RANDBETWEEN(1,10) -> 2 | ... AG7: =RANDBETWEEN(1,10) -> 1 | AH7: =IF(SUM($C7:$AG7)>0,SUM($C7:$AG7),"") -> 181 | AI7: 392 | AJ7: 420 | AK7: =AJ7-AI7 -> 28 | AL7: =AJ7*AH7 -> 76020 | AM7: =AK7*AH7 -> 5068 | AO7: Expanses
B8: Cetaphil | C8: =RANDBETWEEN(1,10) -> 9 | D8: =RANDBETWEEN(1,10) -> 6 | E8: =RANDBETWEEN(1,10) -> 8 | F8: =RANDBETWEEN(1,10) -> 6 | G8: =RANDBETWEEN(1,10) -> 5 | H8: =RANDBETWEEN(1,10) -> 9 | I8: =RANDBETWEEN(1,10) -> 5 | J8: =RANDBETWEEN(1,10) -> 6 | ... AG8: =RANDBETWEEN(1,10) -> 3 | AH8: =IF(SUM($C8:$AG8)>0,SUM($C8:$AG8),"") -> 166 | AI8: 86 | AJ8: 100 | AK8: =AJ8-AI8 -> 14 | AL8: =AJ8*AH8 -> 16600 | AM8: =AK8*AH8 -> 2324 | AO8: Employee Salary
B9: Acetaminophen | C9: =RANDBETWEEN(1,10) -> 7 | D9: =RANDBETWEEN(1,10) -> 9 | E9: =RANDBETWEEN(1,10) -> 7 | F9: =RANDBETWEEN(1,10) -> 1 | G9: =RANDBETWEEN(1,10) -> 9 | H9: =RANDBETWEEN(1,10) -> 4 | I9: =RANDBETWEEN(1,10) -> 7 | J9: =RANDBETWEEN(1,10) -> 10 | ... AG9: =RANDBETWEEN(1,10) -> 3 | AH9: =IF(SUM($C9:$AG9)>0,SUM($C9:$AG9),"") -> 170 | AI9: 271 | AJ9: 300 | AK9: =AJ9-AI9 -> 29 | AL9: =AJ9*AH9 -> 51000 | AM9: =AK9*AH9 -> 4930 | AO9: Kaishav(Owner) | AP9: ='Attendence (March)'!AL3 -> 48333.333
B10: Ibuprofen | C10: =RANDBETWEEN(1,10) -> 1 | D10: =RANDBETWEEN(1,10) -> 3 | E10: =RANDBETWEEN(1,10) -> 9 | F10: =RANDBETWEEN(1,10) -> 1 | G10: =RANDBETWEEN(1,10) -> 1 | H10: =RANDBETWEEN(1,10) -> 5 | I10: =RANDBETWEEN(1,10) -> 2 | J10: =RANDBETWEEN(1,10) -> 2 | ... AG10: =RANDBETWEEN(1,10) -> 9 | AH10: =IF(SUM($C10:$AG10)>0,SUM($C10:$AG10),"") -> 177 | AI10: 226 | AJ10: 250 | AK10: =AJ10-AI10 -> 24 | AL10: =AJ10*AH10 -> 44250 | AM10: =AK10*AH10 -> 4248 | AO10: Raman | AP10: ='Attendence (March)'!AL4 -> 14000
B11: Aspirin | C11: =RANDBETWEEN(1,10) -> 1 | D11: =RANDBETWEEN(1,10) -> 5 | E11: =RANDBETWEEN(1,10) -> 10 | F11: =RANDBETWEEN(1,10) -> 7 | G11: =RANDBETWEEN(1,10) -> 8 | H11: =RANDBETWEEN(1,10) -> 1 | I11: =RANDBETWEEN(1,10) -> 6 | J11: =RANDBETWEEN(1,10) -> 6 | ... AG11: =RANDBETWEEN(1,10) -> 1 | AH11: =IF(SUM($C11:$AG11)>0,SUM($C11:$AG11),"") -> 179 | AI11: 390 | AJ11: 450 | AK11: =AJ11-AI11 -> 60 | AL11: =AJ11*AH11 -> 80550 | AM11: =AK11*AH11 -> 10740 | AO11: Sohan | AP11: ='Attendence (March)'!AL5 -> 18000
B12: Amoxicillin | C12: =RANDBETWEEN(1,10) -> 6 | D12: =RANDBETWEEN(1,10) -> 5 | E12: =RANDBETWEEN(1,10) -> 3 | F12: =RANDBETWEEN(1,10) -> 3 | G12: =RANDBETWEEN(1,10) -> 8 | H12: =RANDBETWEEN(1,10) -> 6 | I12: =RANDBETWEEN(1,10) -> 7 | J12: =RANDBETWEEN(1,10) -> 9 | ... AG12: =RANDBETWEEN(1,10) -> 3 | AH12: =IF(SUM($C12:$AG12)>0,SUM($C12:$AG12),"") -> 183 | AI12: 379 | AJ12: 430 | AK12: =AJ12-AI12 -> 51 | AL12: =AJ12*AH12 -> 78690 | AM12: =AK12*AH12 -> 9333 | AO12: Tilak | AP12: ='Attendence (March)'!AL6 -> 9666.6667
B13: Ciprofloxacin | C13: =RANDBETWEEN(1,10) -> 10 | D13: =RANDBETWEEN(1,10) -> 8 | E13: =RANDBETWEEN(1,10) -> 1 | F13: =RANDBETWEEN(1,10) -> 6 | G13: =RANDBETWEEN(1,10) -> 10 | H13: =RANDBETWEEN(1,10) -> 6 | I13: =RANDBETWEEN(1,10) -> 4 | J13: =RANDBETWEEN(1,10) -> 4 | ... AG13: =RANDBETWEEN(1,10) -> 9 | AH13: =IF(SUM($C13:$AG13)>0,SUM($C13:$AG13),"") -> 183 | AI13: 368 | AJ13: 435 | AK13: =AJ13-AI13 -> 67 | AL13: =AJ13*AH13 -> 79605 | AM13: =AK13*AH13 -> 12261 | AO13: Bill to pay | AP13: 10000
B14: Lisinopril | C14: =RANDBETWEEN(1,10) -> 10 | D14: =RANDBETWEEN(1,10) -> 2 | E14: =RANDBETWEEN(1,10) -> 1 | F14: =RANDBETWEEN(1,10) -> 4 | G14: =RANDBETWEEN(1,10) -> 2 | H14: =RANDBETWEEN(1,10) -> 4 | I14: =RANDBETWEEN(1,10) -> 2 | J14: =RANDBETWEEN(1,10) -> 10 | ... AG14: =RANDBETWEEN(1,10) -> 10 | AH14: =IF(SUM($C14:$AG14)>0,SUM($C14:$AG14),"") -> 166 | AI14: 88 | AJ14: 99 | AK14: =AJ14-AI14 -> 11 | AL14: =AJ14*AH14 -> 16434 | AM14: =AK14*AH14 -> 1826 | AO14: other | AP14: 2000
B15: Atorvastatin | C15: =RANDBETWEEN(1,10) -> 1 | D15: =RANDBETWEEN(1,10) -> 6 | E15: =RANDBETWEEN(1,10) -> 8 | F15: =RANDBETWEEN(1,10) -> 4 | G15: =RANDBETWEEN(1,10) -> 6 | H15: =RANDBETWEEN(1,10) -> 6 | I15: =RANDBETWEEN(1,10) -> 2 | J15: =RANDBETWEEN(1,10) -> 5 | ... AG15: =RANDBETWEEN(1,10) -> 4 | AH15: =IF(SUM($C15:$AG15)>0,SUM($C15:$AG15),"") -> 165 | AI15: 391 | AJ15: 500 | AK15: =AJ15-AI15 -> 109 | AL15: =AJ15*AH15 -> 82500 | AM15: =AK15*AH15 -> 17985 | AO15: Net collection | AP15: =SUM(AM3:AM57) -> 295515
B16: Metformin | C16: =RANDBETWEEN(1,10) -> 9 | D16: =RANDBETWEEN(1,10) -> 8 | E16: =RANDBETWEEN(1,10) -> 10 | F16: =RANDBETWEEN(1,10) -> 8 | G16: =RANDBETWEEN(1,10) -> 3 | H16: =RANDBETWEEN(1,10) -> 3 | I16: =RANDBETWEEN(1,10) -> 2 | J16: =RANDBETWEEN(1,10) -> 7 | ... AG16: =RANDBETWEEN(1,10) -> 1 | AH16: =IF(SUM($C16:$AG16)>0,SUM($C16:$AG16),"") -> 159 | AI16: 261 | AJ16: 300 | AK16: =AJ16-AI16 -> 39 | AL16: =AJ16*AH16 -> 47700 | AM16: =AK16*AH16 -> 6201 | AO16: Net Income | AP16: =AP15-(AP9+AP10+AP11+AP12+AP13+AP14) -> 193515
B17: Simvastatin | C17: =RANDBETWEEN(1,10) -> 3 | D17: =RANDBETWEEN(1,10) -> 8 | E17: =RANDBETWEEN(1,10) -> 6 | F17: =RANDBETWEEN(1,10) -> 6 | G17: =RANDBETWEEN(1,10) -> 6 | H17: =RANDBETWEEN(1,10) -> 1 | I17: =RANDBETWEEN(1,10) -> 2 | J17: =RANDBETWEEN(1,10) -> 4 | ... AG17: =RANDBETWEEN(1,10) -> 5 | AH17: =IF(SUM($C17:$AG17)>0,SUM($C17:$AG17),"") -> 175 | AI17: 67 | AJ17: 99 | AK17: =AJ17-AI17 -> 32 | AL17: =AJ17*AH17 -> 17325 | AM17: =AK17*AH17 -> 5600
B18: Omeprazole | C18: =RANDBETWEEN(1,10) -> 1 | D18: =RANDBETWEEN(1,10) -> 10 | E18: =RANDBETWEEN(1,10) -> 9 | F18: =RANDBETWEEN(1,10) -> 8 | G18: =RANDBETWEEN(1,10) -> 6 | H18: =RANDBETWEEN(1,10) -> 5 | I18: =RANDBETWEEN(1,10) -> 1 | J18: =RANDBETWEEN(1,10) -> 9 | ... AG18: =RANDBETWEEN(1,10) -> 2 | AH18: =IF(SUM($C18:$AG18)>0,SUM($C18:$AG18),"") -> 156 | AI18: 138 | AJ18: 150 | AK18: =AJ18-AI18 -> 12 | AL18: =AJ18*AH18 -> 23400 | AM18: =AK18*AH18 -> 1872
B19: Clopidogrel | C19: =RANDBETWEEN(1,10) -> 8 | D19: =RANDBETWEEN(1,10) -> 10 | E19: =RANDBETWEEN(1,10) -> 8 | F19: =RANDBETWEEN(1,10) -> 9 | G19: =RANDBETWEEN(1,10) -> 7 | H19: =RANDBETWEEN(1,10) -> 7 | I19: =RANDBETWEEN(1,10) -> 10 | J19: =RANDBETWEEN(1,10) -> 6 | ... AG19: =RANDBETWEEN(1,10) -> 5 | AH19: =IF(SUM($C19:$AG19)>0,SUM($C19:$AG19),"") -> 182 | AI19: 60 | AJ19: 80 | AK19: =AJ19-AI19 -> 20 | AL19: =AJ19*AH19 -> 14560 | AM19: =AK19*AH19 -> 3640
B20: Metoprolol | C20: =RANDBETWEEN(1,10) -> 8 | D20: =RANDBETWEEN(1,10) -> 6 | E20: =RANDBETWEEN(1,10) -> 4 | F20: =RANDBETWEEN(1,10) -> 7 | G20: =RANDBETWEEN(1,10) -> 1 | H20: =RANDBETWEEN(1,10) -> 7 | I20: =RANDBETWEEN(1,10) -> 1 | J20: =RANDBETWEEN(1,10) -> 9 | ... AG20: =RANDBETWEEN(1,10) -> 2 | AH20: =IF(SUM($C20:$AG20)>0,SUM($C20:$AG20),"") -> 144 | AI20: 44 | AJ20: 50 | AK20: =AJ20-AI20 -> 6 | AL20: =AJ20*AH20 -> 7200 | AM20: =AK20*AH20 -> 864
B21: Amlodipine | C21: =RANDBETWEEN(1,10) -> 6 | D21: =RANDBETWEEN(1,10) -> 5 | E21: =RANDBETWEEN(1,10) -> 3 | F21: =RANDBETWEEN(1,10) -> 3 | G21: =RANDBETWEEN(1,10) -> 5 | H21: =RANDBETWEEN(1,10) -> 4 | I21: =RANDBETWEEN(1,10) -> 2 | J21: =RANDBETWEEN(1,10) -> 4 | ... AG21: =RANDBETWEEN(1,10) -> 5 | AH21: =IF(SUM($C21:$AG21)>0,SUM($C21:$AG21),"") -> 139 | AI21: 308 | AJ21: 320 | AK21: =AJ21-AI21 -> 12 | AL21: =AJ21*AH21 -> 44480 | AM21: =AK21*AH21 -> 1668
B22: Alprazolam | C22: =RANDBETWEEN(1,10) -> 7 | D22: =RANDBETWEEN(1,10) -> 7 | E22: =RANDBETWEEN(1,10) -> 5 | F22: =RANDBETWEEN(1,10) -> 10 | G22: =RANDBETWEEN(1,10) -> 5 | H22: =RANDBETWEEN(1,10) -> 6 | I22: =RANDBETWEEN(1,10) -> 3 | J22: =RANDBETWEEN(1,10) -> 6 | ... AG22: =RANDBETWEEN(1,10) -> 9 | AH22: =IF(SUM($C22:$AG22)>0,SUM($C22:$AG22),"") -> 162 | AI22: 234 | AJ22: 250 | AK22: =AJ22-AI22 -> 16 | AL22: =AJ22*AH22 -> 40500 | AM22: =AK22*AH22 -> 2592
B23: Hydrocodone | C23: =RANDBETWEEN(1,10) -> 1 | D23: =RANDBETWEEN(1,10) -> 2 | E23: =RANDBETWEEN(1,10) -> 9 | F23: =RANDBETWEEN(1,10) -> 4 | G23: =RANDBETWEEN(1,10) -> 6 | H23: =RANDBETWEEN(1,10) -> 8 | I23: =RANDBETWEEN(1,10) -> 7 | J23: =RANDBETWEEN(1,10) -> 8 | ... AG23: =RANDBETWEEN(1,10) -> 3 | AH23: =IF(SUM($C23:$AG23)>0,SUM($C23:$AG23),"") -> 156 | AI23: 121 | AJ23: 140 | AK23: =AJ23-AI23 -> 19 | AL23: =AJ23*AH23 -> 21840 | AM23: =AK23*AH23 -> 2964
B24: Gabapentin | C24: =RANDBETWEEN(1,10) -> 9 | D24: =RANDBETWEEN(1,10) -> 9 | E24: =RANDBETWEEN(1,10) -> 6 | F24: =RANDBETWEEN(1,10) -> 1 | G24: =RANDBETWEEN(1,10) -> 9 | H24: =RANDBETWEEN(1,10) -> 9 | I24: =RANDBETWEEN(1,10) -> 5 | J24: =RANDBETWEEN(1,10) -> 2 | ... AG24: =RANDBETWEEN(1,10) -> 5 | AH24: =IF(SUM($C24:$AG24)>0,SUM($C24:$AG24),"") -> 178 | AI24: 350 | AJ24: 390 | AK24: =AJ24-AI24 -> 40 | AL24: =AJ24*AH24 -> 69420 | AM24: =AK24*AH24 -> 7120
B25: Levothyroxine | C25: =RANDBETWEEN(1,10) -> 2 | D25: =RANDBETWEEN(1,10) -> 2 | E25: =RANDBETWEEN(1,10) -> 9 | F25: =RANDBETWEEN(1,10) -> 10 | G25: =RANDBETWEEN(1,10) -> 5 | H25: =RANDBETWEEN(1,10) -> 6 | I25: =RANDBETWEEN(1,10) -> 2 | J25: =RANDBETWEEN(1,10) -> 5 | ... AG25: =RANDBETWEEN(1,10) -> 2 | AH25: =IF(SUM($C25:$AG25)>0,SUM($C25:$AG25),"") -> 161 | AI25: 211 | AJ25: 240 | AK25: =AJ25-AI25 -> 29 | AL25: =AJ25*AH25 -> 38640 | AM25: =AK25*AH25 -> 4669
B26: Sertraline | C26: =RANDBETWEEN(1,10) -> 1 | D26: =RANDBETWEEN(1,10) -> 10 | E26: =RANDBETWEEN(1,10) -> 6 | F26: =RANDBETWEEN(1,10) -> 7 | G26: =RANDBETWEEN(1,10) -> 3 | H26: =RANDBETWEEN(1,10) -> 3 | I26: =RANDBETWEEN(1,10) -> 6 | J26: =RANDBETWEEN(1,10) -> 3 | ... AG26: =RANDBETWEEN(1,10) -> 8 | AH26: =IF(SUM($C26:$AG26)>0,SUM($C26:$AG26),"") -> 146 | AI26: 247 | AJ26: 280 | AK26: =AJ26-AI26 -> 33 | AL26: =AJ26*AH26 -> 40880 | AM26: =AK26*AH26 -> 4818
B27: Azithromycin | C27: =RANDBETWEEN(1,10) -> 3 | D27: =RANDBETWEEN(1,10) -> 7 | E27: =RANDBETWEEN(1,10) -> 4 | F27: =RANDBETWEEN(1,10) -> 2 | G27: =RANDBETWEEN(1,10) -> 9 | H27: =RANDBETWEEN(1,10) -> 6 | I27: =RANDBETWEEN(1,10) -> 8 | J27: =RANDBETWEEN(1,10) -> 3 | ... AG27: =RANDBETWEEN(1,10) -> 6 | AH27: =IF(SUM($C27:$AG27)>0,SUM($C27:$AG27),"") -> 178 | AI27: 286 | AJ27: 320 | AK27: =AJ27-AI27 -> 34 | AL27: =AJ27*AH27 -> 56960 | AM27: =AK27*AH27 -> 6052
B28: Losartan | C28: =RANDBETWEEN(1,10) -> 1 | D28: =RANDBETWEEN(1,10) -> 4 | E28: =RANDBETWEEN(1,10) -> 5 | F28: =RANDBETWEEN(1,10) -> 9 | G28: =RANDBETWEEN(1,10) -> 9 | H28: =RANDBETWEEN(1,10) -> 6 | I28: =RANDBETWEEN(1,10) -> 8 | J28: =RANDBETWEEN(1,10) -> 2 | ... AG28: =RANDBETWEEN(1,10) -> 10 | AH28: =IF(SUM($C28:$AG28)>0,SUM($C28:$AG28),"") -> 192 | AI28: 67 | AJ28: 80 | AK28: =AJ28-AI28 -> 13 | AL28: =AJ28*AH28 -> 15360 | AM28: =AK28*AH28 -> 2496
... B57: Lamotrigine | C57: =RANDBETWEEN(1,10) -> 6 | D57: =RANDBETWEEN(1,10) -> 8 | E57: =RANDBETWEEN(1,10) -> 1 | F57: =RANDBETWEEN(1,10) -> 6 | G57: =RANDBETWEEN(1,10) -> 6 | H57: =RANDBETWEEN(1,10) -> 9 | I57: =RANDBETWEEN(1,10) -> 1 | J57: =RANDBETWEEN(1,10) -> 6 | ... AG57: =RANDBETWEEN(1,10) -> 4 | AH57: =IF(SUM($C57:$AG57)>0,SUM($C57:$AG57),"") -> 153 | AI57: 340 | AJ57: 380 | AK57: =AJ57-AI57 -> 40 | AL57: =AJ57*AH57 -> 58140 | AM57: =AK57*AH57 -> 6120

Sheet Aprail
C1: =TEXT(C2,"DDD") -> #VALUE! | D1: =TEXT(D2,"DDD") -> #VALUE! | E1: =TEXT(E2,"DDD") -> #VALUE! | F1: =TEXT(F2,"DDD") -> #VALUE! | G1: =TEXT(G2,"DDD") -> #VALUE! | H1: =TEXT(H2,"DDD") -> #VALUE! | I1: =TEXT(I2,"DDD") -> #VALUE! | J1: =TEXT(J2,"DDD") -> #VALUE! | ... AF1: =TEXT(AF2,"DDD") -> #VALUE! | AH1: Total Sales | AI1: Incoming price (Including GST) | AJ1: Sales price | AK1: Profit Margin | AL1: Total collection | AM1: Net collection | AO1: Month | AP1: Aprail
B2: Product Name | C2: =IF(COLUMNS($C$2:C2)>DAY($AP$4),"",$AP$3+COLUMNS($C$2:C2)-1) -> #VALUE! | D2: =IF(COLUMNS($C$2:D2)>DAY($AP$4),"",$AP$3+COLUMNS($C$2:D2)-1) -> #VALUE! | E2: =IF(COLUMNS($C$2:E2)>DAY($AP$4),"",$AP$3+COLUMNS($C$2:E2)-1) -> #VALUE! | F2: =IF(COLUMNS($C$2:F2)>DAY($AP$4),"",$AP$3+COLUMNS($C$2:F2)-1) -> #VALUE! | G2: =IF(COLUMNS($C$2:G2)>DAY($AP$4),"",$AP$3+COLUMNS($C$2:G2)-1) -> #VALUE! | H2: =IF(COLUMNS($C$2:H2)>DAY($AP$4),"",$AP$3+COLUMNS($C$2:H2)-1) -> #VALUE! | I2: =IF(COLUMNS($C$2:I2)>DAY($AP$4),"",$AP$3+COLUMNS($C$2:I2)-1) -> #VALUE! | J2: =IF(COLUMNS($C$2:J2)>DAY($AP$4),"",$AP$3+COLUMNS($C$2:J2)-1) -> #VALUE! | ... AF2: =IF(COLUMNS($C$2:AF2)>DAY($AP$4),"",$AP$3+COLUMNS($C$2:AF2)-1) -> #VALUE! | AO2: Year | AP2: 2024
B3: Iodex | C3: =RANDBETWEEN(1,10) -> 7 | D3: =RANDBETWEEN(1,10) -> 10 | E3: =RANDBETWEEN(1,10) -> 2 | F3: =RANDBETWEEN(1,10) -> 4 | G3: =RANDBETWEEN(1,10) -> 8 | H3: =RANDBETWEEN(1,10) -> 3 | I3: =RANDBETWEEN(1,10) -> 4 | J3: =RANDBETWEEN(1,10) -> 1 | ... AF3: =RANDBETWEEN(1,10) -> 5 | AH3: =IF(SUM($C3:$AG3)>0,SUM($C3:$AG3),"") -> 137 | AI3: 40 | AJ3: 80 | AK3: =AJ3-AI3 -> 40 | AL3: =AJ3*AH3 -> 10960 | AM3: =AK3*AH3 -> 5480 | AO3: Starting Date | AP3: =DATE(AP2,MONTH(AP1&1),1) -> #VALUE!
B4: Nimocet | C4: =RANDBETWEEN(1,10) -> 6 | D4: =RANDBETWEEN(1,10) -> 6 | E4: =RANDBETWEEN(1,10) -> 10 | F4: =RANDBETWEEN(1,10) -> 7 | G4: =RANDBETWEEN(1,10) -> 2 | H4: =RANDBETWEEN(1,10) -> 5 | I4: =RANDBETWEEN(1,10) -> 6 | J4: =RANDBETWEEN(1,10) -> 8 | ... AF4: =RANDBETWEEN(1,10) -> 3 | AH4: =IF(SUM($C4:$AG4)>0,SUM($C4:$AG4),"") -> 157 | AI4: 7 | AJ4: 15 | AK4: =AJ4-AI4 -> 8 | AL4: =AJ4*AH4 -> 2355 | AM4: =AK4*AH4 -> 1256 | AO4: Ending Date | AP4: =EOMONTH(AP3,0) -> #VALUE!
B5: Paracetamol | C5: =RANDBETWEEN(1,10) -> 1 | D5: =RANDBETWEEN(1,10) -> 6 | E5: =RANDBETWEEN(1,10) -> 5 | F5: =RANDBETWEEN(1,10) -> 4 | G5: =RANDBETWEEN(1,10) -> 10 | H5: =RANDBETWEEN(1,10) -> 2 | I5: =RANDBETWEEN(1,10) -> 5 | J5: =RANDBETWEEN(1,10) -> 2 | ... AF5: =RANDBETWEEN(1,10) -> 4 | AH5: =IF(SUM($C5:$AG5)>0,SUM($C5:$AG5),"") -> 172 | AI5: 5 | AJ5: 10 | AK5: =AJ5-AI5 -> 5 | AL5: =AJ5*AH5 -> 1720 | AM5: =AK5*AH5 -> 860
B6: Monocef | C6: =RANDBETWEEN(1,10) -> 9 | D6: =RANDBETWEEN(1,10) -> 1 | E6: =RANDBETWEEN(1,10) -> 7 | F6: =RANDBETWEEN(1,10) -> 1 | G6: =RANDBETWEEN(1,10) -> 6 | H6: =RANDBETWEEN(1,10) -> 10 | I6: =RANDBETWEEN(1,10) -> 5 | J6: =RANDBETWEEN(1,10) -> 10 | ... AF6: =RANDBETWEEN(1,10) -> 3 | AH6: =IF(SUM($C6:$AG6)>0,SUM($C6:$AG6),"") -> 167 | AI6: 45 | AJ6: 80 | AK6: =AJ6-AI6 -> 35 | AL6: =AJ6*AH6 -> 13360 | AM6: =AK6*AH6 -> 5845
B7: Cyclopalm | C7: =RANDBETWEEN(1,10) -> 8 | D7: =RANDBETWEEN(1,10) -> 6 | E7: =RANDBETWEEN(1,10) -> 6 | F7: =RANDBETWEEN(1,10) -> 7 | G7: =RANDBETWEEN(1,10) -> 3 | H7: =RANDBETWEEN(1,10) -> 3 | I7: =RANDBETWEEN(1,10) -> 9 | J7: =RANDBETWEEN(1,10) -> 3 | ... AF7: =RANDBETWEEN(1,10) -> 4 | AH7: =IF(SUM($C7:$AG7)>0,SUM($C7:$AG7),"") -> 171 | AI7: 392 | AJ7: 420 | AK7: =AJ7-AI7 -> 28 | AL7: =AJ7*AH7 -> 71820 | AM7: =AK7*AH7 -> 4788 | AO7: Expanses
B8: Cetaphil | C8: =RANDBETWEEN(1,10) -> 10 | D8: =RANDBETWEEN(1,10) -> 4 | E8: =RANDBETWEEN(1,10) -> 4 | F8: =RANDBETWEEN(1,10) -> 8 | G8: =RANDBETWEEN(1,10) -> 6 | H8: =RANDBETWEEN(1,10) -> 1 | I8: =RANDBETWEEN(1,10) -> 3 | J8: =RANDBETWEEN(1,10) -> 10 | ... AF8: =RANDBETWEEN(1,10) -> 3 | AH8: =IF(SUM($C8:$AG8)>0,SUM($C8:$AG8),"") -> 181 | AI8: 86 | AJ8: 100 | AK8: =AJ8-AI8 -> 14 | AL8: =AJ8*AH8 -> 18100 | AM8: =AK8*AH8 -> 2534 | AO8: Employee Salary
B9: Acetaminophen | C9: =RANDBETWEEN(1,10) -> 7 | D9: =RANDBETWEEN(1,10) -> 2 | E9: =RANDBETWEEN(1,10) -> 2 | F9: =RANDBETWEEN(1,10) -> 8 | G9: =RANDBETWEEN(1,10) -> 2 | H9: =RANDBETWEEN(1,10) -> 8 | I9: =RANDBETWEEN(1,10) -> 6 | J9: =RANDBETWEEN(1,10) -> 7 | ... AF9: =RANDBETWEEN(1,10) -> 9 | AH9: =IF(SUM($C9:$AG9)>0,SUM($C9:$AG9),"") -> 174 | AI9: 271 | AJ9: 300 | AK9: =AJ9-AI9 -> 29 | AL9: =AJ9*AH9 -> 52200 | AM9: =AK9*AH9 -> 5046 | AO9: Kaishav(Owner) | AP9: ='Attendence (Aprail)'!AL3 -> 48333.333
B10: Ibuprofen | C10: =RANDBETWEEN(1,10) -> 4 | D10: =RANDBETWEEN(1,10) -> 3 | E10: =RANDBETWEEN(1,10) -> 2 | F10: =RANDBETWEEN(1,10) -> 4 | G10: =RANDBETWEEN(1,10) -> 3 | H10: =RANDBETWEEN(1,10) -> 8 | I10: =RANDBETWEEN(1,10) -> 6 | J10: =RANDBETWEEN(1,10) -> 10 | ... AF10: =RANDBETWEEN(1,10) -> 2 | AH10: =IF(SUM($C10:$AG10)>0,SUM($C10:$AG10),"") -> 166 | AI10: 226 | AJ10: 250 | AK10: =AJ10-AI10 -> 24 | AL10: =AJ10*AH10 -> 41500 | AM10: =AK10*AH10 -> 3984 | AO10: Raman | AP10: ='Attendence (Aprail)'!AL4 -> 14000
B11: Aspirin | C11: =RANDBETWEEN(1,10) -> 7 | D11: =RANDBETWEEN(1,10) -> 8 | E11: =RANDBETWEEN(1,10) -> 3 | F11: =RANDBETWEEN(1,10) -> 5 | G11: =RANDBETWEEN(1,10) -> 5 | H11: =RANDBETWEEN(1,10) -> 1 | I11: =RANDBETWEEN(1,10) -> 10 | J11: =RANDBETWEEN(1,10) -> 3 | ... AF11: =RANDBETWEEN(1,10) -> 5 | AH11: =IF(SUM($C11:$AG11)>0,SUM($C11:$AG11),"") -> 159 | AI11: 390 | AJ11: 450 | AK11: =AJ11-AI11 -> 60 | AL11: =AJ11*AH11 -> 71550 | AM11: =AK11*AH11 -> 9540 | AO11: Sohan | AP11: ='Attendence (Aprail)'!AL5 -> 17400
B12: Amoxicillin | C12: =RANDBETWEEN(1,10) -> 8 | D12: =RANDBETWEEN(1,10) -> 4 | E12: =RANDBETWEEN(1,10) -> 10 | F12: =RANDBETWEEN(1,10) -> 1 | G12: =RANDBETWEEN(1,10) -> 5 | H12: =RANDBETWEEN(1,10) -> 3 | I12: =RANDBETWEEN(1,10) -> 3 | J12: =RANDBETWEEN(1,10) -> 1 | ... AF12: =RANDBETWEEN(1,10) -> 9 | AH12: =IF(SUM($C12:$AG12)>0,SUM($C12:$AG12),"") -> 155 | AI12: 379 | AJ12: 430 | AK12: =AJ12-AI12 -> 51 | AL12: =AJ12*AH12 -> 66650 | AM12: =AK12*AH12 -> 7905 | AO12: Tilak | AP12: ='Attendence (Aprail)'!AL6 -> 9666.6667
B13: Ciprofloxacin | C13: =RANDBETWEEN(1,10) -> 9 | D13: =RANDBETWEEN(1,10) -> 1 | E13: =RANDBETWEEN(1,10) -> 2 | F13: =RANDBETWEEN(1,10) -> 8 | G13: =RANDBETWEEN(1,10) -> 3 | H13: =RANDBETWEEN(1,10) -> 4 | I13: =RANDBETWEEN(1,10) -> 10 | J13: =RANDBETWEEN(1,10) -> 5 | ... AF13: =RANDBETWEEN(1,10) -> 6 | AH13: =IF(SUM($C13:$AG13)>0,SUM($C13:$AG13),"") -> 169 | AI13: 368 | AJ13: 435 | AK13: =AJ13-AI13 -> 67 | AL13: =AJ13*AH13 -> 73515 | AM13: =AK13*AH13 -> 11323 | AO13: Bill to pay | AP13: 10000
B14: Lisinopril | C14: =RANDBETWEEN(1,10) -> 3 | D14: =RANDBETWEEN(1,10) -> 3 | E14: =RANDBETWEEN(1,10) -> 9 | F14: =RANDBETWEEN(1,10) -> 10 | G14: =RANDBETWEEN(1,10) -> 10 | H14: =RANDBETWEEN(1,10) -> 2 | I14: =RANDBETWEEN(1,10) -> 3 | J14: =RANDBETWEEN(1,10) -> 7 | ... AF14: =RANDBETWEEN(1,10) -> 6 | AH14: =IF(SUM($C14:$AG14)>0,SUM($C14:$AG14),"") -> 153 | AI14: 88 | AJ14: 99 | AK14: =AJ14-AI14 -> 11 | AL14: =AJ14*AH14 -> 15147 | AM14: =AK14*AH14 -> 1683 | AO14: other | AP14: 2000
B15: Atorvastatin | C15: =RANDBETWEEN(1,10) -> 7 | D15: =RANDBETWEEN(1,10) -> 4 | E15: =RANDBETWEEN(1,10) -> 9 | F15: =RANDBETWEEN(1,10) -> 4 | G15: =RANDBETWEEN(1,10) -> 7 | H15: =RANDBETWEEN(1,10) -> 9 | I15: =RANDBETWEEN(1,10) -> 10 | J15: =RANDBETWEEN(1,10) -> 7 | ... AF15: =RANDBETWEEN(1,10) -> 3 | AH15: =IF(SUM($C15:$AG15)>0,SUM($C15:$AG15),"") -> 183 | AI15: 391 | AJ15: 500 | AK15: =AJ15-AI15 -> 109 | AL15: =AJ15*AH15 -> 91500 | AM15: =AK15*AH15 -> 19947 | AO15: Net collection | AP15: =SUM(AM3:AM57) -> 282392
B16: Metformin | C16: =RANDBETWEEN(1,10) -> 10 | D16: =RANDBETWEEN(1,10) -> 8 | E16: =RANDBETWEEN(1,10) -> 6 | F16: =RANDBETWEEN(1,10) -> 4 | G16: =RANDBETWEEN(1,10) -> 10 | H16: =RANDBETWEEN(1,10) -> 5 | I16: =RANDBETWEEN(1,10) -> 7 | J16: =RANDBETWEEN(1,10) -> 9 | ... AF16: =RANDBETWEEN(1,10) -> 2 | AH16: =IF(SUM($C16:$AG16)>0,SUM($C16:$AG16),"") -> 162 | AI16: 261 | AJ16: 300 | AK16: =AJ16-AI16 -> 39 | AL16: =AJ16*AH16 -> 48600 | AM16: =AK16*AH16 -> 6318 | AO16: Net Income | AP16: =AP15-(AP9+AP10+AP11+AP12+AP13+AP14) -> 180992
B17: Simvastatin | C17: =RANDBETWEEN(1,10) -> 6 | D17: =RANDBETWEEN(1,10) -> 9 | E17: =RANDBETWEEN(1,10) -> 1 | F17: =RANDBETWEEN(1,10) -> 4 | G17: =RANDBETWEEN(1,10) -> 5 | H17: =RANDBETWEEN(1,10) -> 2 | I17: =RANDBETWEEN(1,10) -> 10 | J17: =RANDBETWEEN(1,10) -> 7 | ... AF17: =RANDBETWEEN(1,10) -> 2 | AH17: =IF(SUM($C17:$AG17)>0,SUM($C17:$AG17),"") -> 140 | AI17: 67 | AJ17: 99 | AK17: =AJ17-AI17 -> 32 | AL17: =AJ17*AH17 -> 13860 | AM17: =AK17*AH17 -> 4480
B18: Omeprazole | C18: =RANDBETWEEN(1,10) -> 8 | D18: =RANDBETWEEN(1,10) -> 6 | E18: =RANDBETWEEN(1,10) -> 6 | F18: =RANDBETWEEN(1,10) -> 7 | G18: =RANDBETWEEN(1,10) -> 9 | H18: =RANDBETWEEN(1,10) -> 3 | I18: =RANDBETWEEN(1,10) -> 7 | J18: =RANDBETWEEN(1,10) -> 7 | ... AF18: =RANDBETWEEN(1,10) -> 4 | AH18: =IF(SUM($C18:$AG18)>0,SUM($C18:$AG18),"") -> 166 | AI18: 138 | AJ18: 150 | AK18: =AJ18-AI18 -> 12 | AL18: =AJ18*AH18 -> 24900 | AM18: =AK18*AH18 -> 1992
B19: Clopidogrel | C19: =RANDBETWEEN(1,10) -> 4 | D19: =RANDBETWEEN(1,10) -> 4 | E19: =RANDBETWEEN(1,10) -> 3 | F19: =RANDBETWEEN(1,10) -> 6 | G19: =RANDBETWEEN(1,10) -> 3 | H19: =RANDBETWEEN(1,10) -> 2 | I19: =RANDBETWEEN(1,10) -> 5 | J19: =RANDBETWEEN(1,10) -> 3 | ... AF19: =RANDBETWEEN(1,10) -> 1 | AH19: =IF(SUM($C19:$AG19)>0,SUM($C19:$AG19),"") -> 123 | AI19: 60 | AJ19: 80 | AK19: =AJ19-AI19 -> 20 | AL19: =AJ19*AH19 -> 9840 | AM19: =AK19*AH19 -> 2460
B20: Metoprolol | C20: =RANDBETWEEN(1,10) -> 8 | D20: =RANDBETWEEN(1,10) -> 8 | E20: =RANDBETWEEN(1,10) -> 4 | F20: =RANDBETWEEN(1,10) -> 6 | G20: =RANDBETWEEN(1,10) -> 3 | H20: =RANDBETWEEN(1,10) -> 3 | I20: =RANDBETWEEN(1,10) -> 4 | J20: =RANDBETWEEN(1,10) -> 9 | ... AF20: =RANDBETWEEN(1,10) -> 10 | AH20: =IF(SUM($C20:$AG20)>0,SUM($C20:$AG20),"") -> 194 | AI20: 44 | AJ20: 50 | AK20: =AJ20-AI20 -> 6 | AL20: =AJ20*AH20 -> 9700 | AM20: =AK20*AH20 -> 1164
B21: Amlodipine | C21: =RANDBETWEEN(1,10) -> 6 | D21: =RANDBETWEEN(1,10) -> 5 | E21: =RANDBETWEEN(1,10) -> 4 | F21: =RANDBETWEEN(1,10) -> 7 | G21: =RANDBETWEEN(1,10) -> 10 | H21: =RANDBETWEEN(1,10) -> 8 | I21: =RANDBETWEEN(1,10) -> 2 | J21: =RANDBETWEEN(1,10) -> 8 | ... AF21: =RANDBETWEEN(1,10) -> 6 | AH21: =IF(SUM($C21:$AG21)>0,SUM($C21:$AG21),"") -> 162 | AI21: 308 | AJ21: 320 | AK21: =AJ21-AI21 -> 12 | AL21: =AJ21*AH21 -> 51840 | AM21: =AK21*AH21 -> 1944
B22: Alprazolam | C22: =RANDBETWEEN(1,10) -> 2 | D22: =RANDBETWEEN(1,10) -> 1 | E22: =RANDBETWEEN(1,10) -> 5 | F22: =RANDBETWEEN(1,10) -> 10 | G22: =RANDBETWEEN(1,10) -> 6 | H22: =RANDBETWEEN(1,10) -> 1 | I22: =RANDBETWEEN(1,10) -> 10 | J22: =RANDBETWEEN(1,10) -> 4 | ... AF22: =RANDBETWEEN(1,10) -> 8 | AH22: =IF(SUM($C22:$AG22)>0,SUM($C22:$AG22),"") -> 167 | AI22: 234 | AJ22: 250 | AK22: =AJ22-AI22 -> 16 | AL22: =AJ22*AH22 -> 41750 | AM22: =AK22*AH22 -> 2672
B23: Hydrocodone | C23: =RANDBETWEEN(1,10) -> 3 | D23: =RANDBETWEEN(1,10) -> 10 | E23: =RANDBETWEEN(1,10) -> 1 | F23: =RANDBETWEEN(1,10) -> 2 | G23: =RANDBETWEEN(1,10) -> 8 | H23: =RANDBETWEEN(1,10) -> 9 | I23: =RANDBETWEEN(1,10) -> 4 | J23: =RANDBETWEEN(1,10) -> 7 | ... AF23: =RANDBETWEEN(1,10) -> 9 | AH23: =IF(SUM($C23:$AG23)>0,SUM($C23:$AG23),"") -> 173 | AI23: 121 | AJ23: 140 | AK23: =AJ23-AI23 -> 19 | AL23: =AJ23*AH23 -> 24220 | AM23: =AK23*AH23 -> 3287
B24: Gabapentin | C24: =RANDBETWEEN(1,10) -> 2 | D24: =RANDBETWEEN(1,10) -> 4 | E24: =RANDBETWEEN(1,10) -> 2 | F24: =RANDBETWEEN(1,10) -> 7 | G24: =RANDBETWEEN(1,10) -> 3 | H24: =RANDBETWEEN(1,10) -> 9 | I24: =RANDBETWEEN(1,10) -> 8 | J24: =RANDBETWEEN(1,10) -> 4 | ... AF24: =RANDBETWEEN(1,10) -> 5 | AH24: =IF(SUM($C24:$AG24)>0,SUM($C24:$AG24),"") -> 156 | AI24: 350 | AJ24: 390 | AK24: =AJ24-AI24 -> 40 | AL24: =AJ24*AH24 -> 60840 | AM24: =AK24*AH24 -> 6240
B25: Levothyroxine | C25: =RANDBETWEEN(1,10) -> 10 | D25: =RANDBETWEEN(1,10) -> 4 | E25: =RANDBETWEEN(1,10) -> 8 | F25: =RANDBETWEEN(1,10) -> 2 | G25: =RANDBETWEEN(1,10) -> 4 | H25: =RANDBETWEEN(1,10) -> 1 | I25: =RANDBETWEEN(1,10) -> 7 | J25: =RANDBETWEEN(1,10) -> 10 | ... AF25: =RANDBETWEEN(1,10) -> 2 | AH25: =IF(SUM($C25:$AG25)>0,SUM($C25:$AG25),"") -> 192 | AI25: 211 | AJ25: 240 | AK25: =AJ25-AI25 -> 29 | AL25: =AJ25*AH25 -> 46080 | AM25: =AK25*AH25 -> 5568
B26: Sertraline | C26: =RANDBETWEEN(1,10) -> 4 | D26: =RANDBETWEEN(1,10) -> 5 | E26: =RANDBETWEEN(1,10) -> 5 | F26: =RANDBETWEEN(1,10) -> 5 | G26: =RANDBETWEEN(1,10) -> 9 | H26: =RANDBETWEEN(1,10) -> 6 | I26: =RANDBETWEEN(1,10) -> 9 | J26: =RANDBETWEEN(1,10) -> 2 | ... AF26: =RANDBETWEEN(1,10) -> 8 | AH26: =IF(SUM($C26:$AG26)>0,SUM($C26:$AG26),"") -> 171 | AI26: 247 | AJ26: 280 | AK26: =AJ26-AI26 -> 33 | AL26: =AJ26*AH26 -> 47880 | AM26: =AK26*AH26 -> 5643
